Workbook

Sheet Sản lượng ký kết
B1: 2023 | C1: BẢNG TỔNG HỢP SẢN LƯỢNG KÝ KẾT TỪ 01/01/2023 đến 17/01/2024
A2: STT | B2: Nội dung | C2: Tháng 1 | D2: Tháng 2 | E2: Tháng 3 | F2: Tháng 4 | G2: Tháng 5 | H2: Tháng 6 | I2: Tháng 7 | J2: Tháng 8 | K2: Tháng 9 | L2: Tháng 10 | M2: Tháng 11 | N2: Tháng 12 | O2: Tổng tháng | P2: Kế hoạch năm | Q2: Tỷ lệ % hoàn thành KH
A3: I | B3: Phần mềm xây dựng | C3: =sum(C4:C5) -> 18.4 | D3: =sum(D4:D5) -> 24.3 | E3: =sum(E4:E5) -> 303.55 | F3: =sum(F4:F5) -> 1041.289 | G3: =sum(G4:G5) -> 692.1 | H3: =sum(H4:H5) -> 15.8 | I3: =sum(I4:I5) -> 42.45 | J3: =sum(J4:J5) -> 24.75 | ... N3: =sum(N4:N5) -> 51.4 | O3: =sum(C3:N3) -> 3467.198 | P3: =SUM(P4:P5) -> 2900 | Q3: =O3/P3 -> 1.1955855
B4: =hyperlink("https://docs.google.com/spreadsheets/d/1w54z4NbyEbyjjJVyXvIK7OhyvnYLbtg7H9uK4YAXpNU/edit#gid=0","- Trung tâm PMXD") -> - Trung tâm PMXD | C4: 4 | D4: 22.3 | E4: 293.1 | F4: 1032.539 | G4: 685.3 | H4: 7.8 | I4: 27.3 | J4: 12 | K4: 447 | L4: 745.659 | M4: 33.8 | N4: 39 | O4: =sum(C4:N4) -> 3349.798 | P4: 2600 | Q4: =O4/P4 -> 1.2883838
B5: =hyperlink("https://docs.google.com/spreadsheets/d/1P0ilCSyqA3dOMst3KNMcZ42cxp71XvTpe3tKMhYksN8/edit#gid=2074483897","- Chi nhánh") -> - Chi nhánh | C5: 14.4 | D5: 2 | E5: 10.45 | F5: 8.75 | G5: 6.8 | H5: 8 | I5: 15.15 | J5: 12.75 | K5: 10 | L5: 1.5 | M5: 15.2 | N5: 12.4 | O5: =sum(C5:N5) -> 117.4 | P5: 300 | Q5: =O5/P5 -> 0.39133333
A6: II | B6: Phần mềm XD Nhập khẩu | C6: =SUM(C7:C8) -> 11141.87 | D6: =SUM(D7:D8) -> 4449.9044 | E6: =SUM(E7:E8) -> 6862.7008 | F6: =SUM(F7:F8) -> 3969.1376 | G6: =SUM(G7:G8) -> 13220.954 | H6: =SUM(H7:H8) -> 5686.3563 | I6: =SUM(I7:I8) -> 5404.8948 | J6: =SUM(J7:J8) -> 9946.7327 | ... N6: =SUM(N7:N8) -> 11714.546 | O6: =sum(C6:N6) -> 104350.01 | P6: =P8+P7 -> 67000 | Q6: =O6/P6 -> 1.5574629
B7: =hyperlink("https://docs.google.com/spreadsheets/d/1vCOoengzj4u-lf-Olvw85ysitfzOfclGKPXAtoEPy0A/edit#gid=663001998","- Trung tâm DCS") -> - Trung tâm DCS | C7: 9685.523 | D7: 1880.838 | E7: 3351.417 | F7: 1907.985 | G7: 8056.9432 | H7: 2855.0532 | I7: 1569.616 | J7: 7299.0959 | K7: 15528.049 | L7: 2349.481 | M7: 4238.9521 | N7: 9274.1166 | O7: =sum(C7:N7) -> 67997.07 | P7: 32000 | Q7: =O7/P7 -> 2.1249084
B8: =hyperlink("https://docs.google.com/spreadsheets/d/1P0ilCSyqA3dOMst3KNMcZ42cxp71XvTpe3tKMhYksN8/edit#gid=1340171929","- Chi nhánh") -> - Chi nhánh | C8: 1456.3474 | D8: 2569.0664 | E8: 3511.2838 | F8: 2061.1526 | G8: 5164.0109 | H8: 2831.3031 | I8: 3835.2788 | J8: 2647.6368 | K8: 1471.8172 | L8: 2102.0449 | M8: 6262.5726 | N8: 2440.4292 | O8: =sum(C8:N8) -> 36352.944 | P8: 35000 | Q8: =O8/P8 -> 1.0386555
A9: III | B9: =hyperlink("https://docs.google.com/spreadsheets/d/1d_dnULuhyFhAz_vzHPOr4a1463PBw6xMA3MZaClxQ5Q/edit#gid=0","Trung tâm STC") -> Trung tâm STC | C9: 330 | D9: 917.62 | E9: 12937.962 | G9: 0 | H9: 2379.4071 | I9: 270.721 | J9: 2629.784 | K9: 2637.5 | L9: 1976.1523 | M9: 3975.407 | N9: 1280.2142 | O9: =sum(C9:N9) -> 29334.768 | P9: =29000*3.8/4 -> 27550 | Q9: =O9/P9 -> 1.0647829
A10: VI | B10: =hyperlink("https://docs.google.com/spreadsheets/d/15oR4AzHb3aObQVH2-iOM0BUe860L_hQgGGLP9Y6meI0/edit#gid=0","Trung tâm TVDA") -> Trung tâm TVDA | C10: 0 | D10: 0 | E10: 328.76373 | F10: 0 | G10: 0 | H10: 0 | I10: 2.16 | J10: 26.028 | K10: 11.265 | L10: 210.968 | M10: 44.16042 | N10: 0 | O10: =sum(C10:N10) -> 623.34515 | P10: 1500 | Q10: =O10/P10 -> 0.41556344
A11: V | B11: =hyperlink("https://docs.google.com/spreadsheets/d/1hB-HxXul-KU7Tqz0qiYJ2YdQ3FS-235QFmwHQIzdQR0/edit#gid=0","Trung tâm TVXD") -> Trung tâm TVXD | C11: 0 | F11: 0 | G11: 0 | I11: 0 | L11: 0 | M11: 0 | N11: 0 | O11: =sum(C11:N11) -> 0 | P11: 3000 | Q11: =O11/P11 -> 0
A12: VI | B12: =HYPERLINK("https://docs.google.com/spreadsheets/d/1_2CNBES8nIYbHQusNB5GWqUCMVnT3BGVbsPgLxWwUCw/edit#gid=0","Trung tâm TMB") -> Trung tâm TMB | C12: 0 | D12: 308 | E12: 5.3 | F12: 36.5 | G12: 125 | H12: 0 | I12: 140 | J12: 45.8 | K12: 60 | L12: 0 | M12: 260.22 | N12: 0 | O12: =sum(C12:N12) -> 980.82 | P12: 6500 | Q12: =O12/P12 -> 0.15089538
A13: VII | B13: =HYPERLINK("https://docs.google.com/spreadsheets/d/1zDciZ8Q2y6PpEHkfkC5QQmjwMAmv6-RHvnczqFOvtSQ/edit#gid=0","Các lĩnh vực khác") -> Các lĩnh vực khác | C13: 0 | O13: =sum(C13:N13) -> 0 | P13: 1000 | Q13: =O13/P13 -> 0
A14: VIII | B14: Tổng chung toàn CT | C14: =SUM(C15:C16) -> 11490.27 | D14: =SUM(D15:D16) -> 5699.8244 | E14: =SUM(E15:E16) -> 20438.277 | F14: =SUM(F15:F16) -> 5046.9266 | G14: =SUM(G15:G16) -> 14038.054 | H14: =SUM(H15:H16) -> 8081.5633 | I14: =SUM(I15:I16) -> 5860.2258 | J14: =SUM(J15:J16) -> 12673.095 | ... N14: =SUM(N15:N16) -> 13046.16 | O14: =sum(C14:N14) -> 138756.14 | P14: =P16+P15 -> 109450 | Q14: =O14/P14 -> 1.2677583
B15: CIC Hà Nội | C15: =C4+C7+C9+C10+C11+C12+C13 -> 10019.523 | D15: =D4+D7+D9+D10+D11+D12+D13 -> 3128.758 | E15: =E4+E7+E9+E10+E11+E12+E13 -> 16916.543 | F15: =F4+F7+F9+F10+F11+F12+F13 -> 2977.024 | G15: =G4+G7+G9+G10+G11+G12+G13 -> 8867.2432 | H15: =H4+H7+H9+H10+H11+H12+H13 -> 5242.2603 | I15: =I4+I7+I9+I10+I11+I12+I13 -> 2009.797 | J15: =J4+J7+J9+J10+J11+J12+J13 -> 10012.708 | ... N15: =N4+N7+N9+N10+N11+N12+N13 -> 10593.331 | O15: =SUM(C15:N15) -> 102285.8 | P15: =P4+P7+P9+P10+P11+P12+P13 -> 74150 | Q15: =O15/P15 -> 1.3794444
B16: CIC Hồ Chí Minh | C16: =C5+C8 -> 1470.7474 | D16: =D5+D8 -> 2571.0664 | E16: =E5+E8 -> 3521.7338 | F16: =F5+F8 -> 2069.9026 | G16: =G5+G8 -> 5170.8109 | H16: =H5+H8 -> 2839.3031 | I16: =I5+I8 -> 3850.4288 | J16: =J5+J8 -> 2660.3868 | ... N16: =N5+N8 -> 2452.8292 | O16: =SUM(C16:N16) -> 36470.344 | P16: =P5+P8 -> 35300 | Q16: =O16/P16 -> 1.0331542
B17: Toàn công ty 2022 | C17: =IFERROR(__xludf.DUMMYFUNCTION("IMPORTRANGE(""1pVVPsJRZuZTfMAbYsuMVtd5oqiAJQKt_FCZMxv4OMEk"", ""Sản lượng ký kết!C14"")"),1952.0050999999999) -> 1952.0051 | D17: =IFERROR(__xludf.DUMMYFUNCTION("IMPORTRANGE(""1pVVPsJRZuZTfMAbYsuMVtd5oqiAJQKt_FCZMxv4OMEk"", ""Sản lượng ký kết!D14"")"),10282.0078) -> 10282.008 | E17: =IFERROR(__xludf.DUMMYFUNCTION("IMPORTRANGE(""1pVVPsJRZuZTfMAbYsuMVtd5oqiAJQKt_FCZMxv4OMEk"", ""Sản lượng ký kết!E14"")"),8027.8570629999995) -> 8027.8571 | F17: =IFERROR(__xludf.DUMMYFUNCTION("IMPORTRANGE(""1pVVPsJRZuZTfMAbYsuMVtd5oqiAJQKt_FCZMxv4OMEk"", ""Sản lượng ký kết!f14"")"),4496.32245) -> 4496.3224 | G17: =IFERROR(__xludf.DUMMYFUNCTION("IMPORTRANGE(""1pVVPsJRZuZTfMAbYsuMVtd5oqiAJQKt_FCZMxv4OMEk"", ""Sản lượng ký kết!g14"")"),7986.195795) -> 7986.1958 | H17: =IFERROR(__xludf.DUMMYFUNCTION("IMPORTRANGE(""1pVVPsJRZuZTfMAbYsuMVtd5oqiAJQKt_FCZMxv4OMEk"", ""Sản lượng ký kết!h14"")"),9755.56469) -> 9755.5647 | I17: =IFERROR(__xludf.DUMMYFUNCTION("IMPORTRANGE(""1pVVPsJRZuZTfMAbYsuMVtd5oqiAJQKt_FCZMxv4OMEk"", ""Sản lượng ký kết!i14"")"),12048.8342) -> 12048.834 | J17: =IFERROR(__xludf.DUMMYFUNCTION("IMPORTRANGE(""1pVVPsJRZuZTfMAbYsuMVtd5oqiAJQKt_FCZMxv4OMEk"", ""Sản lượng ký kết!j14"")"),6463.7398) -> 6463.7398 | K17: =IFERROR(__xludf.DUMMYFUNCTION("IMPORTRANGE(""1pVVPsJRZuZTfMAbYsuMVtd5oqiAJQKt_FCZMxv4OMEk"", ""Sản lượng ký kết!k14"")"),10128.5694) -> 10128.569 | L17: =IFERROR(__xludf.DUMMYFUNCTION("IMPORTRANGE(""1pVVPsJRZuZTfMAbYsuMVtd5oqiAJQKt_FCZMxv4OMEk"", ""Sản lượng ký kết!l14"")"),15853.552585) -> 15853.553 | M17: =IFERROR(__xludf.DUMMYFUNCTION("IMPORTRANGE(""1pVVPsJRZuZTfMAbYsuMVtd5oqiAJQKt_FCZMxv4OMEk"", ""Sản lượng ký kết!m14"")"),18714.146304) -> 18714.146 | N17: =IFERROR(__xludf.DUMMYFUNCTION("IMPORTRANGE(""1pVVPsJRZuZTfMAbYsuMVtd5oqiAJQKt_FCZMxv4OMEk"", ""Sản lượng ký kết!n14"")"),7567.379999999999) -> 7567.38 | O17: =SUM(C17:N17) -> 113276.18
B18: So sánh 2023/2022 | C18: =C14/C17 -> 5.8863936 | D18: =D14/D17 -> 0.55434936 | E18: =E14/E17 -> 2.5459194 | F18: =F14/F17 -> 1.1224566 | G18: =G14/G17 -> 1.7577899 | H18: =H14/H17 -> 0.82840549 | I18: =I14/I17 -> 0.48637285 | J18: =J14/J17 -> 1.9606443 | ... O18: =O14/O17 -> 1.2249367
B19: SS cùng kỳ năm ngoái | D19: =sum($C14:D14)/sum($C17:D17) -> 1.4051068 | E19: =sum($C14:E14)/sum($C17:E17) -> 1.8571026 | F19: =sum($C14:F14)/sum($C17:F17) -> 1.7236839 | G19: =sum($C14:G14)/sum($C17:G17) -> 1.7320022 | H19: =sum($C14:H14)/sum($C17:H17) -> 1.5245879 | I19: =sum($C14:I14)/sum($C17:I17) -> 1.2952651 | J19: =sum($C14:J14)/sum($C17:J17) -> 1.3657562 | K19: =sum($C14:K14)/sum($C17:K17) -> 1.4547691 | ... N19: =sum($C14:N14)/sum($C17:N17) -> 1.2249367 | O19: Kế hoạch # | P19: 70000 | Q19: =O14/P19 -> 1.9822306

Sheet Tổng hợp Doanh thu
B1: 2023 | C1: BẢNG TỔNG HỢP DOANH THU TỪ 01/01/2023 đến 17/01/2024
A2: STT | B2: Nội dung | C2: Tháng 1 | D2: Tháng 2 | E2: Tháng 3 | F2: Tháng 4 | G2: Tháng 5 | H2: Tháng 6 | I2: Tháng 7 | J2: Tháng 8 | K2: Tháng 9 | L2: Tháng 10 | M2: Tháng 11 | N2: Tháng 12 | O2: Tổng tháng | P2: Kế hoạch năm | Q2: Tỷ lệ % hoàn thành KH
A3: I | B3: Phần mềm xây dựng | C3: =sum(C4:C5) -> 10 | D3: =sum(D4:D5) -> 43.9 | E3: =sum(E4:E5) -> 52.95 | F3: =sum(F4:F5) -> 8.75 | G3: =sum(G4:G5) -> 15.3 | H3: =sum(H4:H5) -> 9.5 | I3: =sum(I4:I5) -> 46.65 | J3: =sum(J4:J5) -> 21.15 | ... N3: =sum(N4:N5) -> 1738.6524 | O3: =sum(C3:N3) -> 3230.8742 | P3: =SUM(P4:P5) -> 2800 | Q3: =O3/P3 -> 1.1538837
B4: =hyperlink("https://docs.google.com/spreadsheets/d/1w54z4NbyEbyjjJVyXvIK7OhyvnYLbtg7H9uK4YAXpNU/edit#gid=0","- Trung tâm PMXD") -> - Trung tâm PMXD | C4: 10 | D4: 27.5 | E4: 42.5 | G4: 8.5 | H4: 9.5 | I4: 23.5 | J4: 8.4 | K4: 8 | L4: 708.31481 | M4: 541.00707 | N4: 1726.2524 | O4: =sum(C4:N4) -> 3113.4742 | P4: 2500 | Q4: =O4/P4 -> 1.2453897
B5: =hyperlink("https://docs.google.com/spreadsheets/d/1P0ilCSyqA3dOMst3KNMcZ42cxp71XvTpe3tKMhYksN8/edit#gid=2074483897","- Chi nhánh") -> - Chi nhánh | D5: 16.4 | E5: 10.45 | F5: 8.75 | G5: 6.8 | I5: 23.15 | J5: 12.75 | K5: 11.5 | M5: 15.2 | N5: 12.4 | O5: =sum(C5:N5) -> 117.4 | P5: 300 | Q5: =O5/P5 -> 0.39133333
A6: II | B6: Phần mềm XD Nhập khẩu | C6: =SUM(C7:C8) -> 951.9737 | D6: =SUM(D7:D8) -> 4962.0367 | E6: =SUM(E7:E8) -> 5151.4492 | F6: =SUM(F7:F8) -> 3746.5291 | G6: =SUM(G7:G8) -> 5929.4705 | H6: =SUM(H7:H8) -> 5736.5642 | I6: =SUM(I7:I8) -> 6067.4328 | J6: =SUM(J7:J8) -> 5086.5611 | ... N6: =SUM(N7:N8) -> 16445.659 | O6: =sum(C6:N6) -> 84946.162 | P6: =P8+P7 -> 61000 | Q6: =O6/P6 -> 1.39256
B7: =hyperlink("https://docs.google.com/spreadsheets/d/1vCOoengzj4u-lf-Olvw85ysitfzOfclGKPXAtoEPy0A/edit#gid=663001998","- Trung tâm DCS") -> - Trung tâm DCS | C7: 303.47 | D7: 3142.641 | E7: 2863.042 | F7: 895.629 | G7: 2789.8042 | H7: 2533.5432 | I7: 2742.481 | J7: 2252.642 | K7: 6715.881 | L7: 5581.3965 | M7: 9497.0535 | N7: 10312.373 | O7: =sum(C7:N7) -> 49629.957 | P7: 28000 | Q7: =O7/P7 -> 1.7724985
B8: =hyperlink("https://docs.google.com/spreadsheets/d/1P0ilCSyqA3dOMst3KNMcZ42cxp71XvTpe3tKMhYksN8/edit#gid=1340171929","- Chi nhánh") -> - Chi nhánh | C8: 648.5037 | D8: 1819.3957 | E8: 2288.4072 | F8: 2850.9001 | G8: 3139.6663 | H8: 3203.021 | I8: 3324.9518 | J8: 2833.9191 | K8: 3270.5666 | L8: 4158.7922 | M8: 1644.795 | N8: 6133.286 | O8: =sum(C8:N8) -> 35316.205 | P8: 33000 | Q8: =O8/P8 -> 1.070188
A9: III | B9: =hyperlink("https://docs.google.com/spreadsheets/d/1d_dnULuhyFhAz_vzHPOr4a1463PBw6xMA3MZaClxQ5Q/edit#gid=0","Trung tâm STC") -> Trung tâm STC | C9: 240 | D9: 381 | F9: 1200.2023 | G9: 14286.377 | H9: 515.58408 | I9: 246.11 | J9: 963.07551 | K9: 662.31 | L9: 2789.837 | M9: 2633.3673 | N9: 3007.136 | O9: =sum(C9:N9) -> 26924.999 | P9: =27000*3.8/4 -> 25650 | Q9: =O9/P9 -> 1.0497076
A10: VI | B10: =hyperlink("https://docs.google.com/spreadsheets/d/15oR4AzHb3aObQVH2-iOM0BUe860L_hQgGGLP9Y6meI0/edit#gid=0","Trung tâm TVDA") -> Trung tâm TVDA | D10: 13.31 | H10: 14.265713 | J10: 2 | K10: 6.936111 | M10: 87.87037 | N10: 525.42759 | O10: =sum(C10:N10) -> 649.80978 | P10: 1500 | Q10: =O10/P10 -> 0.43320652
A11: V | B11: =hyperlink("https://docs.google.com/spreadsheets/d/1hB-HxXul-KU7Tqz0qiYJ2YdQ3FS-235QFmwHQIzdQR0/edit#gid=0","Trung tâm TVXD") -> Trung tâm TVXD | F11: 147.46718 | H11: 6.913636 | L11: 172.54545 | M11: 147.33064 | O11: =sum(C11:N11) -> 474.25691 | P11: 2500 | Q11: =O11/P11 -> 0.18970276
A12: VI | B12: =HYPERLINK("https://docs.google.com/spreadsheets/d/1_2CNBES8nIYbHQusNB5GWqUCMVnT3BGVbsPgLxWwUCw/edit#gid=0","Trung tâm TMB") -> Trung tâm TMB | D12: 6 | F12: 4 | G12: 36.5 | H12: 304 | J12: 163.3 | K12: 65 | N12: 498.3 | O12: =sum(C12:N12) -> 1077.1 | P12: 5500 | Q12: =O12/P12 -> 0.19583636
A13: VII | B13: =HYPERLINK("https://docs.google.com/spreadsheets/d/1zDciZ8Q2y6PpEHkfkC5QQmjwMAmv6-RHvnczqFOvtSQ/edit#gid=0","Các lĩnh vực khác") -> Các lĩnh vực khác | O13: 0 | P13: 600 | Q13: =O13/P13 -> 0
A14: VIII | B14: Tổng chung toàn CT | C14: =SUM(C15:C16) -> 1201.9737 | D14: =SUM(D15:D16) -> 5406.2467 | E14: =SUM(E15:E16) -> 5204.3992 | F14: =SUM(F15:F16) -> 5106.9486 | G14: =SUM(G15:G16) -> 20267.647 | H14: =SUM(H15:H16) -> 6586.8277 | I14: =SUM(I15:I16) -> 6360.1928 | J14: =SUM(J15:J16) -> 6236.0866 | ... N14: =SUM(N15:N16) -> 22215.175 | O14: =sum(C14:N14) -> 117303.2 | P14: =P16+P15 -> 99550 | Q14: =O14/P14 -> 1.1783345
B15: CIC Hà Nội | C15: =C4+C7+C9+C10+C11+C12+C13 -> 553.47 | D15: =D4+D7+D9+D10+D11+D12+D13 -> 3570.451 | E15: =E4+E7+E9+E10+E11+E12+E13 -> 2905.542 | F15: =F4+F7+F9+F10+F11+F12+F13 -> 2247.2985 | G15: =G4+G7+G9+G10+G11+G12+G13 -> 17121.181 | H15: =H4+H7+H9+H10+H11+H12+H13 -> 3383.8067 | I15: =I4+I7+I9+I10+I11+I12+I13 -> 3012.091 | J15: =J4+J7+J9+J10+J11+J12+J13 -> 3389.4175 | ... N15: =N4+N7+N9+N10+N11+N12+N13 -> 16069.489 | O15: =SUM(C15:N15) -> 81869.596 | P15: =P4+P7+P9+P10+P11+P12+P13 -> 66250 | Q15: =O15/P15 -> 1.2357675
B16: CIC Hồ Chí Minh | C16: =C5+C8 -> 648.5037 | D16: =D5+D8 -> 1835.7957 | E16: =E5+E8 -> 2298.8572 | F16: =F5+F8 -> 2859.6501 | G16: =G5+G8 -> 3146.4663 | H16: =H5+H8 -> 3203.021 | I16: =I5+I8 -> 3348.1018 | J16: =J5+J8 -> 2846.6691 | ... N16: =N5+N8 -> 6145.686 | O16: =SUM(C16:N16) -> 35433.605 | P16: =P5+P8 -> 33300 | Q16: =O16/P16 -> 1.0640722
B17: Toàn công ty 2022 | C17: =IFERROR(__xludf.DUMMYFUNCTION("IMPORTRANGE(""1pVVPsJRZuZTfMAbYsuMVtd5oqiAJQKt_FCZMxv4OMEk"", ""Tổng hợp doanh thu!C14"")"),2003.068225) -> 2003.0682 | D17: =IFERROR(__xludf.DUMMYFUNCTION("IMPORTRANGE(""1pVVPsJRZuZTfMAbYsuMVtd5oqiAJQKt_FCZMxv4OMEk"", ""Tổng hợp doanh thu!D14"")"),6958.6287) -> 6958.6287 | E17: =IFERROR(__xludf.DUMMYFUNCTION("IMPORTRANGE(""1pVVPsJRZuZTfMAbYsuMVtd5oqiAJQKt_FCZMxv4OMEk"", ""Tổng hợp doanh thu!E14"")"),12906.04008) -> 12906.04 | F17: =IFERROR(__xludf.DUMMYFUNCTION("IMPORTRANGE(""1pVVPsJRZuZTfMAbYsuMVtd5oqiAJQKt_FCZMxv4OMEk"", ""Tổng hợp doanh thu!F14"")"),6338.346294) -> 6338.3463 | G17: =IFERROR(__xludf.DUMMYFUNCTION("IMPORTRANGE(""1pVVPsJRZuZTfMAbYsuMVtd5oqiAJQKt_FCZMxv4OMEk"", ""Tổng hợp doanh thu!G14"")"),4492.21257) -> 4492.2126 | H17: =IFERROR(__xludf.DUMMYFUNCTION("IMPORTRANGE(""1pVVPsJRZuZTfMAbYsuMVtd5oqiAJQKt_FCZMxv4OMEk"", ""Tổng hợp doanh thu!H14"")"),6505.181455) -> 6505.1815 | I17: =IFERROR(__xludf.DUMMYFUNCTION("IMPORTRANGE(""1pVVPsJRZuZTfMAbYsuMVtd5oqiAJQKt_FCZMxv4OMEk"", ""Tổng hợp doanh thu!I14"")"),8380.832808000001) -> 8380.8328 | J17: =IFERROR(__xludf.DUMMYFUNCTION("IMPORTRANGE(""1pVVPsJRZuZTfMAbYsuMVtd5oqiAJQKt_FCZMxv4OMEk"", ""Tổng hợp doanh thu!J14"")"),5473.4193190000005) -> 5473.4193 | K17: =IFERROR(__xludf.DUMMYFUNCTION("IMPORTRANGE(""1pVVPsJRZuZTfMAbYsuMVtd5oqiAJQKt_FCZMxv4OMEk"", ""Tổng hợp doanh thu!K14"")"),4044.6675450000002) -> 4044.6675 | L17: =IFERROR(__xludf.DUMMYFUNCTION("IMPORTRANGE(""1pVVPsJRZuZTfMAbYsuMVtd5oqiAJQKt_FCZMxv4OMEk"", ""Tổng hợp doanh thu!L14"")"),9801.598005) -> 9801.598 | M17: =IFERROR(__xludf.DUMMYFUNCTION("IMPORTRANGE(""1pVVPsJRZuZTfMAbYsuMVtd5oqiAJQKt_FCZMxv4OMEk"", ""Tổng hợp doanh thu!M14"")"),6418.566651) -> 6418.5667 | N17: =IFERROR(__xludf.DUMMYFUNCTION("IMPORTRANGE(""1pVVPsJRZuZTfMAbYsuMVtd5oqiAJQKt_FCZMxv4OMEk"", ""Tổng hợp doanh thu!N14"")"),38801.643201444436) -> 38801.643 | O17: =SUM(C17:N17) -> 112124.2
B18: So sánh 2023/2022 | C18: =C14/C17 -> 0.60006628 | D18: =D14/D17 -> 0.77691266 | E18: =E14/E17 -> 0.40325299 | F18: =F14/F17 -> 0.80572255 | G18: =G14/G17 -> 4.5117293 | H18: =H14/H17 -> 1.012551 | I18: =I14/I17 -> 0.75889747 | J18: =J14/J17 -> 1.1393402 | ... O18: =O14/O17 -> 1.0461898
B19: SS cùng kỳ năm ngoái | D19: =sum($C14:D14)/sum($C17:D17) -> 0.73738495 | E19: =sum($C14:E14)/sum($C17:E17) -> 0.54018482 | F19: =sum($C14:F14)/sum($C17:F17) -> 0.59985529 | G19: =sum($C14:G14)/sum($C17:G17) -> 1.137283 | H19: =sum($C14:H14)/sum($C17:H17) -> 1.1165857 | I19: =sum($C14:I14)/sum($C17:I17) -> 1.0535875 | J19: =sum($C14:J14)/sum($C17:J17) -> 1.0624337 | K19: =sum($C14:K14)/sum($C17:K17) -> 1.1752662 | ... N19: =sum($C14:N14)/sum($C17:N17) -> 1.0461898 | O19: Kế hoạch # | P19: 68000 | Q19: =O14/P19 -> 1.7250471

Sheet Lợi nhuận gộp quản trị
B1: 2023 | C1: BẢNG TỔNG HỢP LỢI NHUẬN GỘP QUẢN TRỊ TỪ 01/01/2023 đến 17/01/2024
A2: STT | B2: Nội dung | C2: Tháng 1 | D2: Tháng 2 | E2: Tháng 3 | F2: Tháng 4 | G2: Tháng 5 | H2: Tháng 6 | I2: Tháng 7 | J2: Tháng 8 | K2: Tháng 9 | L2: Tháng 10 | M2: Tháng 11 | N2: Tháng 12 | O2: Tổng tháng | P2: Kế hoạch năm | Q2: Tỷ lệ % hoàn thành KH
A3: I | B3: Phần mềm xây dựng | C3: =sum(C4:C5) -> 11.92 | D3: =sum(D4:D5) -> 23.4 | E3: =sum(E4:E5) -> 94.302045 | F3: =sum(F4:F5) -> 604.74079 | G3: =sum(G4:G5) -> 357.06067 | H3: =sum(H4:H5) -> 12.2 | I3: =sum(I4:I5) -> 35.6325 | J3: =sum(J4:J5) -> 19.0125 | ... N3: =sum(N4:N5) -> 45.82 | O3: =sum(C3:N3) -> 2043.8895 | P3: =SUM(P4:P5) -> 2050 | Q3: =O3/P3 -> 0.99701928
B4: =hyperlink("https://docs.google.com/spreadsheets/d/1w54z4NbyEbyjjJVyXvIK7OhyvnYLbtg7H9uK4YAXpNU/edit#gid=0","- Trung tâm PMXD") -> - Trung tâm PMXD | C4: 4 | D4: 22.3 | E4: 88.554545 | F4: 599.92829 | G4: 353.32067 | H4: 7.8 | I4: 27.3 | J4: 12 | K4: 293.94444 | L4: 497.37157 | M4: 33.8 | N4: 39 | O4: =sum(C4:N4) -> 1979.3195 | P4: 1800 | Q4: =O4/P4 -> 1.099622
B5: =hyperlink("https://docs.google.com/spreadsheets/d/1P0ilCSyqA3dOMst3KNMcZ42cxp71XvTpe3tKMhYksN8/edit#gid=2074483897","- Chi nhánh") -> - Chi nhánh | C5: 7.92 | D5: 1.1 | E5: 5.7475 | F5: 4.8125 | G5: 3.74 | H5: 4.4 | I5: 8.3325 | J5: 7.0125 | K5: 5.5 | L5: 0.825 | M5: 8.36 | N5: 6.82 | O5: =sum(C5:N5) -> 64.57 | P5: 250 | Q5: =O5/P5 -> 0.25828
A6: II | B6: Phần mềm XD Nhập khẩu | C6: =SUM(C7:C8) -> 1601.8086 | D6: =SUM(D7:D8) -> 744.99662 | E6: =SUM(E7:E8) -> 1700.1369 | F6: =SUM(F7:F8) -> 1025.521 | G6: =SUM(G7:G8) -> 1260.9653 | H6: =SUM(H7:H8) -> 1268.0672 | I6: =SUM(I7:I8) -> 1082.9322 | J6: =SUM(J7:J8) -> 1460.2244 | ... N6: =SUM(N7:N8) -> 876.79655 | O6: =sum(C6:N6) -> 16910.152 | P6: =P8+P7 -> 11000 | Q6: =O6/P6 -> 1.5372866
B7: =hyperlink("https://docs.google.com/spreadsheets/d/1vCOoengzj4u-lf-Olvw85ysitfzOfclGKPXAtoEPy0A/edit#gid=663001998","- Trung tâm DCS") -> - Trung tâm DCS | C7: 1442.4958 | D7: 571.03083 | E7: 839.91106 | F7: 616.88319 | G7: 659.63058 | H7: 854.58374 | I7: 390.82412 | J7: 1016.3562 | K7: 1744.5308 | L7: 503.31234 | M7: 826.8029 | N7: 699.14462 | O7: =sum(C7:N7) -> 10165.506 | P7: 5500 | Q7: =O7/P7 -> 1.8482739
B8: =hyperlink("https://docs.google.com/spreadsheets/d/1P0ilCSyqA3dOMst3KNMcZ42cxp71XvTpe3tKMhYksN8/edit#gid=1340171929","- Chi nhánh") -> - Chi nhánh | C8: 159.31275 | D8: 173.96579 | E8: 860.22583 | F8: 408.63782 | G8: 601.33469 | H8: 413.48343 | I8: 692.10807 | J8: 443.86819 | K8: 77.854826 | L8: 213.65601 | M8: 2522.5468 | N8: 177.65193 | O8: =sum(C8:N8) -> 6744.6461 | P8: 5500 | Q8: =O8/P8 -> 1.2262993
A9: III | B9: =hyperlink("https://docs.google.com/spreadsheets/d/1d_dnULuhyFhAz_vzHPOr4a1463PBw6xMA3MZaClxQ5Q/edit#gid=0","Trung tâm STC") -> Trung tâm STC | C9: 93.197808 | D9: 145.44443 | E9: 949.62597 | F9: 0 | G9: 31.5715 | H9: 137.25268 | I9: 74.74961 | J9: 464.15035 | K9: 419.08925 | L9: 200.55004 | M9: 1126.5915 | N9: 270.62572 | O9: =sum(C9:N9) -> 3912.8488 | P9: 3800 | Q9: =O9/P9 -> 1.0296971
A10: V | B10: =hyperlink("https://docs.google.com/spreadsheets/d/15oR4AzHb3aObQVH2-iOM0BUe860L_hQgGGLP9Y6meI0/edit#gid=0","Trung tâm TVDA") -> Trung tâm TVDA | C10: 0 | D10: 0 | E10: 90.403364 | F10: 0 | G10: 0 | H10: 0 | I10: 2 | J10: 15.7855 | K10: 6.831056 | L10: 81.173304 | M10: 27.178278 | N10: 0 | O10: =sum(C10:N10) -> 223.3715 | P10: 1050 | Q10: =O10/P10 -> 0.21273476
A11: VI | B11: =hyperlink("https://docs.google.com/spreadsheets/d/1hB-HxXul-KU7Tqz0qiYJ2YdQ3FS-235QFmwHQIzdQR0/edit#gid=0","Trung tâm TVXD") -> Trung tâm TVXD | C11: 399.25691 | F11: 0 | G11: 0 | I11: 0 | L11: 0 | M11: 0 | N11: 0 | O11: =sum(C11:N11) -> 399.25691 | P11: 1500 | Q11: =O11/P11 -> 0.26617127
A12: VI | B12: =HYPERLINK("https://docs.google.com/spreadsheets/d/1_2CNBES8nIYbHQusNB5GWqUCMVnT3BGVbsPgLxWwUCw/edit#gid=0","Trung tâm TMB") -> Trung tâm TMB | C12: 0 | D12: 144.85325 | E12: 0 | F12: 10.001921 | G12: 53.352891 | H12: 0 | I12: 46.48489 | J12: 16.5744 | K12: 11.745038 | L12: 0 | M12: 85.051889 | N12: 0 | O12: =sum(C12:N12) -> 368.06428 | P12: 1500 | Q12: =O12/P12 -> 0.24537618
A13: VII | B13: =HYPERLINK("https://docs.google.com/spreadsheets/d/1zDciZ8Q2y6PpEHkfkC5QQmjwMAmv6-RHvnczqFOvtSQ/edit#gid=0","Các lĩnh vực khác") -> Các lĩnh vực khác | C13: 0 | O13: =sum(C13:N13) -> 0 | P13: 300 | Q13: =O13/P13 -> 0
A14: VIII | B14: Tổng chung toàn CT | C14: =SUM(C15:C16) -> 2106.1833 | D14: =SUM(D15:D16) -> 1058.6943 | E14: =SUM(E15:E16) -> 2834.4683 | F14: =SUM(F15:F16) -> 1640.2637 | G14: =SUM(G15:G16) -> 1702.9503 | H14: =SUM(H15:H16) -> 1417.5199 | I14: =SUM(I15:I16) -> 1241.7992 | J14: =SUM(J15:J16) -> 1975.7472 | ... N14: =SUM(N15:N16) -> 1193.2423 | O14: =sum(C14:N14) -> 23857.583 | P14: =P16+P15 -> 21200 | Q14: =O14/P14 -> 1.1253577
B15: CIC Hà Nội | C15: =C4+C7+C9+C10+C11+C12+C13 -> 1938.9505 | D15: =D4+D7+D9+D10+D11+D12+D13 -> 883.62851 | E15: =E4+E7+E9+E10+E11+E12+E13 -> 1968.4949 | F15: =F4+F7+F9+F10+F11+F12+F13 -> 1226.8134 | G15: =G4+G7+G9+G10+G11+G12+G13 -> 1097.8756 | H15: =H4+H7+H9+H10+H11+H12+H13 -> 999.63642 | I15: =I4+I7+I9+I10+I11+I12+I13 -> 541.35862 | J15: =J4+J7+J9+J10+J11+J12+J13 -> 1524.8665 | ... N15: =N4+N7+N9+N10+N11+N12+N13 -> 1008.7703 | O15: =SUM(C15:N15) -> 17048.367 | P15: =P4+P7+P9+P10+P11+P12+P13 -> 15450 | Q15: =O15/P15 -> 1.1034542
B16: CIC Hồ Chí Minh | C16: =C5+C8 -> 167.23275 | D16: =D5+D8 -> 175.06579 | E16: =E5+E8 -> 865.97333 | F16: =F5+F8 -> 413.45032 | G16: =G5+G8 -> 605.07469 | H16: =H5+H8 -> 417.88343 | I16: =I5+I8 -> 700.44057 | J16: =J5+J8 -> 450.88069 | ... N16: =N5+N8 -> 184.47193 | O16: =SUM(C16:N16) -> 6809.2161 | P16: =P5+P8 -> 5750 | Q16: =O16/P16 -> 1.1842115
B17: Toàn công ty 2022 | C17: =IFERROR(__xludf.DUMMYFUNCTION("IMPORTRANGE(""1pVVPsJRZuZTfMAbYsuMVtd5oqiAJQKt_FCZMxv4OMEk"", ""Lợi nhuận gộp quản trị!C14"")"),262.0113078888889) -> 262.01131 | D17: =IFERROR(__xludf.DUMMYFUNCTION("IMPORTRANGE(""1pVVPsJRZuZTfMAbYsuMVtd5oqiAJQKt_FCZMxv4OMEk"", ""Lợi nhuận gộp quản trị!D14"")"),1665.8142580977776) -> 1665.8143 | E17: =IFERROR(__xludf.DUMMYFUNCTION("IMPORTRANGE(""1pVVPsJRZuZTfMAbYsuMVtd5oqiAJQKt_FCZMxv4OMEk"", ""Lợi nhuận gộp quản trị!E14"")"),2311.5198993892777) -> 2311.5199 | F17: =IFERROR(__xludf.DUMMYFUNCTION("IMPORTRANGE(""1pVVPsJRZuZTfMAbYsuMVtd5oqiAJQKt_FCZMxv4OMEk"", ""Lợi nhuận gộp quản trị!F14"")"),1255.3343158239645) -> 1255.3343 | G17: =IFERROR(__xludf.DUMMYFUNCTION("IMPORTRANGE(""1pVVPsJRZuZTfMAbYsuMVtd5oqiAJQKt_FCZMxv4OMEk"", ""Lợi nhuận gộp quản trị!G14"")"),1939.806246096496) -> 1939.8062 | H17: =IFERROR(__xludf.DUMMYFUNCTION("IMPORTRANGE(""1pVVPsJRZuZTfMAbYsuMVtd5oqiAJQKt_FCZMxv4OMEk"", ""Lợi nhuận gộp quản trị!H14"")"),1481.4140755772223) -> 1481.4141 | I17: =IFERROR(__xludf.DUMMYFUNCTION("IMPORTRANGE(""1pVVPsJRZuZTfMAbYsuMVtd5oqiAJQKt_FCZMxv4OMEk"", ""Lợi nhuận gộp quản trị!I14"")"),2708.911169673633) -> 2708.9112 | J17: =IFERROR(__xludf.DUMMYFUNCTION("IMPORTRANGE(""1pVVPsJRZuZTfMAbYsuMVtd5oqiAJQKt_FCZMxv4OMEk"", ""Lợi nhuận gộp quản trị!J14"")"),1371.8205878944445) -> 1371.8206 | K17: =IFERROR(__xludf.DUMMYFUNCTION("IMPORTRANGE(""1pVVPsJRZuZTfMAbYsuMVtd5oqiAJQKt_FCZMxv4OMEk"", ""Lợi nhuận gộp quản trị!K14"")"),1508.1248156913095) -> 1508.1248 | L17: =IFERROR(__xludf.DUMMYFUNCTION("IMPORTRANGE(""1pVVPsJRZuZTfMAbYsuMVtd5oqiAJQKt_FCZMxv4OMEk"", ""Lợi nhuận gộp quản trị!L14"")"),2554.0759917589817) -> 2554.076 | M17: =IFERROR(__xludf.DUMMYFUNCTION("IMPORTRANGE(""1pVVPsJRZuZTfMAbYsuMVtd5oqiAJQKt_FCZMxv4OMEk"", ""Lợi nhuận gộp quản trị!M14"")"),3316.250103666192) -> 3316.2501 | N17: =IFERROR(__xludf.DUMMYFUNCTION("IMPORTRANGE(""1pVVPsJRZuZTfMAbYsuMVtd5oqiAJQKt_FCZMxv4OMEk"", ""Lợi nhuận gộp quản trị!N14"")"),1715.060285901111) -> 1715.0603 | O17: =SUM(C17:N17) -> 22090.143
B18: So sánh 2023/2022 | C18: =C14/C17 -> 8.0385206 | D18: =D14/D17 -> 0.63554162 | E18: =E14/E17 -> 1.2262357 | F18: =F14/F17 -> 1.306635 | G18: =G14/G17 -> 0.87789713 | H18: =H14/H17 -> 0.95686944 | I18: =I14/I17 -> 0.45841266 | J18: =J14/J17 -> 1.4402373 | ... O18: =O14/O17 -> 1.0800104
B19: SS cùng kỳ năm ngoái | D19: =sum($C14:D14)/sum($C17:D17) -> 1.6416826 | E19: =sum($C14:E14)/sum($C17:E17) -> 1.4151585 | F19: =sum($C14:F14)/sum($C17:F17) -> 1.3903648 | G19: =sum($C14:G14)/sum($C17:G17) -> 1.2566518 | H19: =sum($C14:H14)/sum($C17:H17) -> 1.2068417 | I19: =sum($C14:I14)/sum($C17:I17) -> 1.0324365 | J19: =sum($C14:J14)/sum($C17:J17) -> 1.0754807 | K19: =sum($C14:K14)/sum($C17:K17) -> 1.1401171 | ... N19: =sum($C14:N14)/sum($C17:N17) -> 1.0800104 | O19: Kế hoạch # | P19: 17000 | Q19: =O14/P19 -> 1.4033873

Sheet Lợi nhuận gộp theo DT
B1: 2023 | C1: BẢNG TỔNG HỢP LỢI NHUẬN GỘP THEO DT TỪ 01/01/2023 đến 17/01/2024
A2: STT | B2: Nội dung | C2: Tháng 1 | D2: Tháng 2 | E2: Tháng 3 | F2: Tháng 4 | G2: Tháng 5 | H2: Tháng 6 | I2: Tháng 7 | J2: Tháng 8 | K2: Tháng 9 | L2: Tháng 10 | M2: Tháng 11 | N2: Tháng 12 | O2: Tổng tháng | P2: Kế hoạch năm | Q2: Tỷ lệ % hoàn thành KH
A3: I | B3: Phần mềm xây dựng | C3: =sum(C4:C5) -> 10 | D3: =sum(D4:D5) -> 30.02 | E3: =sum(E4:E5) -> 48.2475 | F3: =sum(F4:F5) -> 4.8125 | G3: =sum(G4:G5) -> 9.24 | H3: =sum(H4:H5) -> 9.5 | I3: =sum(I4:I5) -> 36.2325 | J3: =sum(J4:J5) -> 15.4125 | ... N3: =sum(N4:N5) -> 1055.3085 | O3: =sum(C3:N3) -> 2033.9895 | P3: =SUM(P4:P5) -> 2050 | Q3: =O3/P3 -> 0.99219001
B4: =hyperlink("https://docs.google.com/spreadsheets/d/1w54z4NbyEbyjjJVyXvIK7OhyvnYLbtg7H9uK4YAXpNU/edit#gid=0","- Trung tâm PMXD") -> - Trung tâm PMXD | C4: 10 | D4: 21 | E4: 42.5 | G4: 5.5 | H4: 9.5 | I4: 23.5 | J4: 8.4 | K4: 8 | L4: 504.67037 | M4: 287.86067 | N4: 1048.4885 | O4: =sum(C4:N4) -> 1969.4195 | P4: ='Lợi nhuận gộp quản trị'!P4 -> 1800 | Q4: =O4/P4 -> 1.094122
B5: =hyperlink("https://docs.google.com/spreadsheets/d/1P0ilCSyqA3dOMst3KNMcZ42cxp71XvTpe3tKMhYksN8/edit#gid=2074483897","- Chi nhánh") -> - Chi nhánh | D5: 9.02 | E5: 5.7475 | F5: 4.8125 | G5: 3.74 | I5: 12.7325 | J5: 7.0125 | K5: 6.325 | M5: 8.36 | N5: 6.82 | O5: =sum(C5:N5) -> 64.57 | P5: ='Lợi nhuận gộp quản trị'!P5 -> 250 | Q5: =O5/P5 -> 0.25828
A6: II | B6: Phần mềm XD Nhập khẩu | C6: =SUM(C7:C8) -> 221.4069 | D6: =SUM(D7:D8) -> 1882.2498 | E6: =SUM(E7:E8) -> 1274.6873 | F6: =SUM(F7:F8) -> 700.20526 | G6: =SUM(G7:G8) -> 1485.2031 | H6: =SUM(H7:H8) -> 872.70414 | I6: =SUM(I7:I8) -> 1100.1296 | J6: =SUM(J7:J8) -> 1116.6839 | ... N6: =SUM(N7:N8) -> 3902.2651 | O6: =sum(C6:N6) -> 16959.985 | P6: =P8+P7 -> 11000 | Q6: =O6/P6 -> 1.5418168
B7: =hyperlink("https://docs.google.com/spreadsheets/d/1vCOoengzj4u-lf-Olvw85ysitfzOfclGKPXAtoEPy0A/edit#gid=663001998","- Trung tâm DCS") -> - Trung tâm DCS | C7: 96.056422 | D7: 1677.0877 | E7: 805.94609 | F7: 237.14365 | G7: 880.25157 | H7: 552.58546 | I7: 437.10509 | J7: 625.91264 | K7: 962.52733 | L7: 1120.2824 | M7: 1132.977 | N7: 1571.5973 | O7: =sum(C7:N7) -> 10099.473 | P7: ='Lợi nhuận gộp quản trị'!P7 -> 5500 | Q7: =O7/P7 -> 1.8362678
B8: =hyperlink("https://docs.google.com/spreadsheets/d/1P0ilCSyqA3dOMst3KNMcZ42cxp71XvTpe3tKMhYksN8/edit#gid=1340171929","- Chi nhánh") -> - Chi nhánh | C8: 125.35048 | D8: 205.1621 | E8: 468.7412 | F8: 463.06161 | G8: 604.95151 | H8: 320.11868 | I8: 663.02453 | J8: 490.77128 | K8: 444.10186 | L8: 318.41048 | M8: 426.15038 | N8: 2330.6678 | O8: =sum(C8:N8) -> 6860.5119 | P8: ='Lợi nhuận gộp quản trị'!P8 -> 5500 | Q8: =O8/P8 -> 1.2473658
A9: III | B9: =hyperlink("https://docs.google.com/spreadsheets/d/1d_dnULuhyFhAz_vzHPOr4a1463PBw6xMA3MZaClxQ5Q/edit#gid=0","Trung tâm STC") -> Trung tâm STC | C9: 17.5 | D9: 109.37183 | F9: 177.04071 | G9: 1085.1902 | H9: 37.55058 | I9: 74.74961 | J9: 175.60613 | K9: 163.92742 | L9: 470.70229 | M9: 604.45804 | N9: 908.99577 | O9: =sum(C9:N9) -> 3825.0926 | P9: ='Lợi nhuận gộp quản trị'!P9 -> 3800 | Q9: =O9/P9 -> 1.0066033
A10: V | B10: =hyperlink("https://docs.google.com/spreadsheets/d/15oR4AzHb3aObQVH2-iOM0BUe860L_hQgGGLP9Y6meI0/edit#gid=0","Trung tâm TVDA") -> Trung tâm TVDA | D10: 9.317 | H10: 9.9859991 | J10: 2 | K10: 6.936111 | M10: 61.509259 | N10: 221.37452 | O10: =sum(C10:N10) -> 311.12289 | P10: ='Lợi nhuận gộp quản trị'!P10 -> 1050 | Q10: =O10/P10 -> 0.29630751
A11: VI | B11: =hyperlink("https://docs.google.com/spreadsheets/d/1hB-HxXul-KU7Tqz0qiYJ2YdQ3FS-235QFmwHQIzdQR0/edit#gid=0","Trung tâm TVXD") -> Trung tâm TVXD | F11: 147.46718 | H11: 6.913636 | L11: 97.545454 | M11: 147.33064 | O11: =sum(C11:N11) -> 399.25691 | P11: ='Lợi nhuận gộp quản trị'!P11 -> 1500 | Q11: =O11/P11 -> 0.26617127
A12: VI | B12: =HYPERLINK("https://docs.google.com/spreadsheets/d/1_2CNBES8nIYbHQusNB5GWqUCMVnT3BGVbsPgLxWwUCw/edit#gid=0","Trung tâm TMB") -> Trung tâm TMB | F12: 1.775 | G12: 10.001921 | H12: 143.07825 | J12: 77.811463 | K12: 16.465656 | N12: 176.96668 | O12: =sum(C12:N12) -> 426.09897 | P12: ='Lợi nhuận gộp quản trị'!P12 -> 1500 | Q12: =O12/P12 -> 0.28406598
A13: VII | B13: =HYPERLINK("https://docs.google.com/spreadsheets/d/1zDciZ8Q2y6PpEHkfkC5QQmjwMAmv6-RHvnczqFOvtSQ/edit#gid=0","Các lĩnh vực khác") -> Các lĩnh vực khác | O13: =sum(C13:N13) -> 0 | P13: ='Lợi nhuận gộp quản trị'!P13 -> 300 | Q13: =O13/P13 -> 0
A14: VIII | B14: Tổng chung toàn CT | C14: =SUM(C15:C16) -> 248.9069 | D14: =SUM(D15:D16) -> 2030.9587 | E14: =SUM(E15:E16) -> 1322.9348 | F14: =SUM(F15:F16) -> 1031.3006 | G14: =SUM(G15:G16) -> 2589.6352 | H14: =SUM(H15:H16) -> 1079.7326 | I14: =SUM(I15:I16) -> 1211.1117 | J14: =SUM(J15:J16) -> 1387.514 | ... N14: =SUM(N15:N16) -> 6264.9106 | O14: =sum(C14:N14) -> 23955.546 | P14: =P16+P15 -> 21200 | Q14: =O14/P14 -> 1.1299786
B15: CIC Hà Nội | C15: =C4+C7+C9+C10+C11+C12+C13 -> 123.55642 | D15: =D4+D7+D9+D10+D11+D12+D13 -> 1816.7766 | E15: =E4+E7+E9+E10+E11+E12+E13 -> 848.44609 | F15: =F4+F7+F9+F10+F11+F12+F13 -> 563.42654 | G15: =G4+G7+G9+G10+G11+G12+G13 -> 1980.9437 | H15: =H4+H7+H9+H10+H11+H12+H13 -> 759.61392 | I15: =I4+I7+I9+I10+I11+I12+I13 -> 535.35469 | J15: =J4+J7+J9+J10+J11+J12+J13 -> 889.73023 | ... N15: =N4+N7+N9+N10+N11+N12+N13 -> 3927.4228 | O15: =SUM(C15:N15) -> 17030.464 | P15: =P4+P7+P9+P10+P11+P12+P13 -> 15450 | Q15: =O15/P15 -> 1.1022954
B16: CIC Hồ Chí Minh | C16: =C5+C8 -> 125.35048 | D16: =D5+D8 -> 214.1821 | E16: =E5+E8 -> 474.4887 | F16: =F5+F8 -> 467.87411 | G16: =G5+G8 -> 608.69151 | H16: =H5+H8 -> 320.11868 | I16: =I5+I8 -> 675.75703 | J16: =J5+J8 -> 497.78378 | ... N16: =N5+N8 -> 2337.4878 | O16: =SUM(C16:N16) -> 6925.0819 | P16: =P5+P8 -> 5750 | Q16: =O16/P16 -> 1.2043621
B17: Toàn công ty 2022 | C17: =IFERROR(__xludf.DUMMYFUNCTION("IMPORTRANGE(""1pVVPsJRZuZTfMAbYsuMVtd5oqiAJQKt_FCZMxv4OMEk"", ""Lợi nhuận gộp theo DT!C14"")"),798.3962012666667) -> 798.3962 | D17: =IFERROR(__xludf.DUMMYFUNCTION("IMPORTRANGE(""1pVVPsJRZuZTfMAbYsuMVtd5oqiAJQKt_FCZMxv4OMEk"", ""Lợi nhuận gộp theo DT!D14"")"),1398.3700036319442) -> 1398.37 | E17: =IFERROR(__xludf.DUMMYFUNCTION("IMPORTRANGE(""1pVVPsJRZuZTfMAbYsuMVtd5oqiAJQKt_FCZMxv4OMEk"", ""Lợi nhuận gộp theo DT!E14"")"),2280.2990185199997) -> 2280.299 | F17: =IFERROR(__xludf.DUMMYFUNCTION("IMPORTRANGE(""1pVVPsJRZuZTfMAbYsuMVtd5oqiAJQKt_FCZMxv4OMEk"", ""Lợi nhuận gộp theo DT!F14"")"),1596.4295453709447) -> 1596.4295 | G17: =IFERROR(__xludf.DUMMYFUNCTION("IMPORTRANGE(""1pVVPsJRZuZTfMAbYsuMVtd5oqiAJQKt_FCZMxv4OMEk"", ""Lợi nhuận gộp theo DT!G14"")"),1207.1216874087963) -> 1207.1217 | H17: =IFERROR(__xludf.DUMMYFUNCTION("IMPORTRANGE(""1pVVPsJRZuZTfMAbYsuMVtd5oqiAJQKt_FCZMxv4OMEk"", ""Lợi nhuận gộp theo DT!H14"")"),1248.4571761485277) -> 1248.4572 | I17: =IFERROR(__xludf.DUMMYFUNCTION("IMPORTRANGE(""1pVVPsJRZuZTfMAbYsuMVtd5oqiAJQKt_FCZMxv4OMEk"", ""Lợi nhuận gộp theo DT!I14"")"),1476.9920664789865) -> 1476.9921 | J17: =IFERROR(__xludf.DUMMYFUNCTION("IMPORTRANGE(""1pVVPsJRZuZTfMAbYsuMVtd5oqiAJQKt_FCZMxv4OMEk"", ""Lợi nhuận gộp theo DT!J14"")"),1397.9229720416665) -> 1397.923 | K17: =IFERROR(__xludf.DUMMYFUNCTION("IMPORTRANGE(""1pVVPsJRZuZTfMAbYsuMVtd5oqiAJQKt_FCZMxv4OMEk"", ""Lợi nhuận gộp theo DT!K14"")"),780.2372479064945) -> 780.23725 | L17: =IFERROR(__xludf.DUMMYFUNCTION("IMPORTRANGE(""1pVVPsJRZuZTfMAbYsuMVtd5oqiAJQKt_FCZMxv4OMEk"", ""Lợi nhuận gộp theo DT!L14"")"),1593.865674128778) -> 1593.8657 | M17: =IFERROR(__xludf.DUMMYFUNCTION("IMPORTRANGE(""1pVVPsJRZuZTfMAbYsuMVtd5oqiAJQKt_FCZMxv4OMEk"", ""Lợi nhuận gộp theo DT!M14"")"),1217.6359650202046) -> 1217.636 | N17: =IFERROR(__xludf.DUMMYFUNCTION("IMPORTRANGE(""1pVVPsJRZuZTfMAbYsuMVtd5oqiAJQKt_FCZMxv4OMEk"", ""Lợi nhuận gộp theo DT!N14"")"),8735.846110960047) -> 8735.8461 | O17: =SUM(C17:N17) -> 23731.574
B18: So sánh 2023/2022 | C18: =C14/C17 -> 0.31175862 | D18: =D14/D17 -> 1.4523757 | E18: =E14/E17 -> 0.58015847 | F18: =F14/F17 -> 0.64600449 | G18: =G14/G17 -> 2.1452976 | H18: =H14/H17 -> 0.86485354 | I18: =I14/I17 -> 0.81998526 | J18: =J14/J17 -> 0.99255398 | ... O18: =O14/O17 -> 1.0094377
B19: SS cùng kỳ năm ngoái | D19: =sum($C14:D14)/sum($C17:D17) -> 1.037828 | E19: =sum($C14:E14)/sum($C17:E17) -> 0.80472367 | F19: =sum($C14:F14)/sum($C17:F17) -> 0.76300403 | G19: =sum($C14:G14)/sum($C17:G17) -> 0.99218745 | H19: =sum($C14:H14)/sum($C17:H17) -> 0.97354874 | I19: =sum($C14:I14)/sum($C17:I17) -> 0.95088128 | J19: =sum($C14:J14)/sum($C17:J17) -> 0.9559896 | K19: =sum($C14:K14)/sum($C17:K17) -> 1.0267684 | ... N19: =sum($C14:N14)/sum($C17:N17) -> 1.0094377 | O19: Kế hoạch # | P19: ='Lợi nhuận gộp quản trị'!P19 -> 17000 | Q19: =O14/P19 -> 1.4091497

Sheet Tổng hợp Tiền về
B1: 2023 | C1: BẢNG TỔNG HỢP TIỀN VỀ TỪ 01/01/2023 đến 17/01/2024
A2: STT | B2: Nội dung | C2: Tháng 1 | D2: Tháng 2 | E2: Tháng 3 | F2: Tháng 4 | G2: Tháng 5 | H2: Tháng 6 | I2: Tháng 7 | J2: Tháng 8 | K2: Tháng 9 | L2: Tháng 10 | M2: Tháng 11 | N2: Tháng 12 | O2: Tổng tháng
A3: I | B3: Phần mềm xây dựng | C3: =sum(C4:C5) -> 2 | D3: =sum(D4:D5) -> 31.6 | E3: =sum(E4:E5) -> 28.25 | F3: =sum(F4:F5) -> 177.2319 | G3: =sum(G4:G5) -> 11.8 | H3: =sum(H4:H5) -> 6.3 | I3: =sum(I4:I5) -> 42.45 | J3: =sum(J4:J5) -> 24.75 | ... N3: =sum(N4:N5) -> 1486.5961 | O3: =sum(C3:N3) -> 3197.045
B4: =hyperlink("https://docs.google.com/spreadsheets/d/1w54z4NbyEbyjjJVyXvIK7OhyvnYLbtg7H9uK4YAXpNU/edit#gid=0","- Trung tâm PMXD") -> - Trung tâm PMXD | C4: 2 | D4: 15.2 | E4: 17.8 | F4: 168.4819 | G4: 5 | H4: 6.3 | I4: 27.3 | J4: 12 | K4: 4 | L4: 773.12 | M4: 582.247 | N4: 1474.1961 | O4: =sum(C4:N4) -> 3087.645
B5: =hyperlink("https://docs.google.com/spreadsheets/d/1P0ilCSyqA3dOMst3KNMcZ42cxp71XvTpe3tKMhYksN8/edit#gid=2074483897","- Chi nhánh") -> - Chi nhánh | D5: 16.4 | E5: 10.45 | F5: 8.75 | G5: 6.8 | I5: 15.15 | J5: 12.75 | K5: 11.5 | M5: 15.2 | N5: 12.4 | O5: =sum(C5:N5) -> 109.4
A6: II | B6: Phần mềm XD Nhập khẩu | C6: =SUM(C7:C8) -> 855.231 | D6: =SUM(D7:D8) -> 4337.8 | E6: =SUM(E7:E8) -> 4299.7954 | F6: =SUM(F7:F8) -> 5385.3988 | G6: =SUM(G7:G8) -> 2511.1659 | H6: =SUM(H7:H8) -> 6847.3694 | I6: =SUM(I7:I8) -> 7159.0317 | J6: =SUM(J7:J8) -> 8293.3154 | ... N6: =SUM(N7:N8) -> 9785.0898 | O6: =sum(C6:N6) -> 75402.399
B7: =hyperlink("https://docs.google.com/spreadsheets/d/1vCOoengzj4u-lf-Olvw85ysitfzOfclGKPXAtoEPy0A/edit#gid=663001998","- Trung tâm DCS") -> - Trung tâm DCS | C7: 59.1 | D7: 2504.066 | E7: 2644.046 | F7: 2737.288 | G7: 919.23 | H7: 3528.6096 | I7: 4442.3156 | J7: 3663.676 | K7: 4160.331 | L7: 7638.4807 | M7: 6263.9384 | N7: 5637.2155 | O7: =sum(C7:N7) -> 44198.297
B8: =hyperlink("https://docs.google.com/spreadsheets/d/1P0ilCSyqA3dOMst3KNMcZ42cxp71XvTpe3tKMhYksN8/edit#gid=1340171929","- Chi nhánh") -> - Chi nhánh | C8: 796.131 | D8: 1833.734 | E8: 1655.7494 | F8: 2648.1108 | G8: 1591.9359 | H8: 3318.7598 | I8: 2716.7161 | J8: 4629.6393 | K8: 2963.559 | L8: 2240.896 | M8: 2660.9965 | N8: 4147.8743 | O8: =sum(C8:N8) -> 31204.102
A9: III | B9: =hyperlink("https://docs.google.com/spreadsheets/d/1d_dnULuhyFhAz_vzHPOr4a1463PBw6xMA3MZaClxQ5Q/edit#gid=0","Trung tâm STC") -> Trung tâm STC | C9: 764 | E9: 3351.4044 | F9: 4189.811 | G9: 1322.0089 | H9: 730.03079 | I9: 1351.8469 | J9: 10296.9 | K9: 844.77329 | L9: 6432.8184 | M9: 2651.3282 | N9: 4379.7746 | O9: =sum(C9:N9) -> 36314.696
A10: V | B10: =hyperlink("https://docs.google.com/spreadsheets/d/15oR4AzHb3aObQVH2-iOM0BUe860L_hQgGGLP9Y6meI0/edit#gid=0","Trung tâm TVDA") -> Trung tâm TVDA | C10: 30 | E10: 14.641 | M10: 821.986 | N10: 10.4436 | O10: =sum(C10:N10) -> 877.0706
A11: VI | B11: =hyperlink("https://docs.google.com/spreadsheets/d/1hB-HxXul-KU7Tqz0qiYJ2YdQ3FS-235QFmwHQIzdQR0/edit#gid=0","Trung tâm TVXD") -> Trung tâm TVXD | D11: 100 | M11: 189.8 | N11: 202.60266 | O11: =sum(C11:N11) -> 492.40266
A12: VI | B12: =HYPERLINK("https://docs.google.com/spreadsheets/d/1_2CNBES8nIYbHQusNB5GWqUCMVnT3BGVbsPgLxWwUCw/edit#gid=0","Trung tâm TMB") -> Trung tâm TMB | C12: 15 | D12: 19 | E12: 147.5 | F12: 18.25 | G12: 77.5 | I12: 197.25 | J12: 54.25 | N12: 153.75 | O12: =sum(C12:N12) -> 682.5
A13: VII | B13: =HYPERLINK("https://docs.google.com/spreadsheets/d/1zDciZ8Q2y6PpEHkfkC5QQmjwMAmv6-RHvnczqFOvtSQ/edit#gid=0","Các lĩnh vực khác") -> Các lĩnh vực khác | O13: =sum(C13:N13) -> 0
A14: VIII | B14: Tổng chung toàn CT | C14: =SUM(C15:C16) -> 1666.231 | D14: =SUM(D15:D16) -> 4488.4 | E14: =SUM(E15:E16) -> 7841.5908 | F14: =SUM(F15:F16) -> 9770.6917 | G14: =SUM(G15:G16) -> 3922.4749 | H14: =SUM(H15:H16) -> 7583.7002 | I14: =SUM(I15:I16) -> 8750.5786 | J14: =SUM(J15:J16) -> 18669.215 | ... N14: =SUM(N15:N16) -> 16018.257 | O14: =sum(C14:N14) -> 116966.11
B15: CIC Hà Nội | C15: =C4+C7+C9+C10+C11+C12+C13 -> 870.1 | D15: =D4+D7+D9+D10+D11+D12+D13 -> 2638.266 | E15: =E4+E7+E9+E10+E11+E12+E13 -> 6175.3914 | F15: =F4+F7+F9+F10+F11+F12+F13 -> 7113.8309 | G15: =G4+G7+G9+G10+G11+G12+G13 -> 2323.7389 | H15: =H4+H7+H9+H10+H11+H12+H13 -> 4264.9404 | I15: =I4+I7+I9+I10+I11+I12+I13 -> 6018.7125 | J15: =J4+J7+J9+J10+J11+J12+J13 -> 14026.826 | ... N15: =N4+N7+N9+N10+N11+N12+N13 -> 11857.982 | O15: =sum(C15:N15) -> 85652.611
B16: CIC Hồ Chí Minh | C16: =C5+C8 -> 796.131 | D16: =D5+D8 -> 1850.134 | E16: =E5+E8 -> 1666.1994 | F16: =F5+F8 -> 2656.8608 | G16: =G5+G8 -> 1598.7359 | H16: =H5+H8 -> 3318.7598 | I16: =I5+I8 -> 2731.8661 | J16: =J5+J8 -> 4642.3893 | ... N16: =N5+N8 -> 4160.2743 | O16: =sum(C16:N16) -> 31313.502

Sheet Thống kê danh sách các hợp đồng
A1: Số hợp đồng | B1: Nội dung hợp đồng | C1: Khách hàng | D1: Ngày ký | E1: Ngày ghi DT | F1: Ký kết | G1: Doanh thu | H1: Lợi nhuận gộp | I1: Tiền về | J1: Tỷ suất LN/DT
F2: =sum(F4:F736)/2 -> 138705844951 | G2: =sum(G4:G736)/2 -> 113215856094 | H2: =sum(H4:H736)/2 -> 23446991506 | I2: =sum(I4:I736)/2 -> 106806382886
F3: =F2/1000000/'Sản lượng ký kết'!P19 -> 1.9815121 | G3: =G2/1000000/'Tổng hợp Doanh thu'!P19 -> 1.6649391 | H3: =H2/1000000/'Lợi nhuận gộp quản trị'!P19 -> 1.3792348
A4: Trung tâm Phần mềm Xây dựng | F4: =sum(F5:F79) -> 3348298000 | G4: =sum(G5:G79) -> 3105474240 | H4: =sum(H5:H79) -> 1977819524 | I4: =sum(I5:I79) -> 3090645000
A5: VV01 | B5: SUMAC | C5: Anh Viễn (Doanh nghiệp tư nhân Trung Thiện Phát) | E5: 45107.583 | F5: 2000000 | G5: 2000000 | H5: 2000000 | I5: 2000000 | J5: =H5/G5 -> 1
A6: vv02/2023 | B6: SUMAC | C6: Công ty CP Đầu tư Xây dựng và Thương Mại TriviCo Hà Nội | E6: 44956.625 | F6: 2000000 | G6: 2000000 | H6: 2000000 | I6: 2000000 | J6: =H6/G6 -> 1
A7: vv03/2023 | B7: Escon 15 | C7: Công Ty TNHH PCCC Đại Việt | E7: 44959.625 | F7: 4000000 | G7: 4000000 | H7: 4000000 | I7: 4000000 | J7: =H7/G7 -> 1
A8: vv04/2023 | B8: Escon 15 | C8: Công Ty TNHH MTV Tư Vấn Thiết Kế Xây Dựng CHD | E8: 44970.625 | F8: 8000000 | G8: 8000000 | H8: 8000000 | I8: 8000000 | J8: =H8/G8 -> 1
A9: vv05/2023 | B9: Stcad | C9: công ty TNHH MTV tư vấn xây dựng Nhân Anh | E9: 44972.625 | F9: 2000000 | G9: 2000000 | H9: 2000000 | I9: 2000000 | J9: =H9/G9 -> 1
A10: VV06 | B10: Escon 15 | C10: CÔNG TY TNHH TM DV KIM PHÁT METAL COLOR | E10: 44975.625 | F10: 1500000 | G10: 1500000 | H10: 1500000 | I10: 1500000 | J10: =H10/G10 -> 1
A11: vv07/2023 | B11: Escon 15 | C11: Viện kiến trúc quy hoạch xây dựng Lào Cai | F11: 300000 | H11: 300000 | J11: =H11/G11 -> #DIV/0!
A12: VV08 | B12: Escon 15 | C12: CÔNG TY CỔ PHẦN XÂY DỰNG VÀ CÔNG NGHỆ MÔI TRƯỜNG QUỐC TẾ | E12: 44979.625 | F12: 1500000 | G12: 1500000 | H12: 1500000 | I12: 1500000 | J12: =H12/G12 -> 1
A13: VV09 | B13: Escon 15 | C13: Công ty CPTVXD Hùng Mạnh | E13: 44979.625 | F13: 4000000 | G13: 4000000 | H13: 4000000 | I13: 4000000 | J13: =H13/G13 -> 1
A14: VV10 | B14: Escon 15 | C14: Lương Lê Long | E14: 45282.625 | F14: 1000000 | G14: 1000000 | H14: 1000000 | I14: 1000000 | J14: =H14/G14 -> 1
A15: vv12/2023 | B15: SUMAC | C15: Cổ phần đầu tư xây dựng và thương mại Trivico Hà Nội | E15: 44987.625 | F15: 2000000 | G15: 2000000 | H15: 2000000 | I15: 2000000 | J15: =H15/G15 -> 1
A16: vv13/2023 | B16: Escon 15 | C16: anh Tuán Anh - Giám Định Lào Cai | E16: 45282.625 | F16: 300000 | G16: 300000 | H16: 300000 | I16: 300000 | J16: =H16/G16 -> 1
A17: vv14/2023 | B17: Escon 15 | C17: Công ty cổ phần xuất nhập khẩu Hà Anh | F17: 300000 | H17: 300000 | J17: =H17/G17 -> #DIV/0!
A18: vv15/2023 | B18: Escon 15 | C18: Công ty TNHH Thiết kế và Xây dựng Q&T Việt Nam | E18: 44992.625 | F18: 1000000 | G18: 1000000 | H18: 1000000 | I18: 1000000 | J18: =H18/G18 -> 1
A19: VV16 | B19: Escon 15 | C19: CÔNG TY TNHH MTV DỊCH VỤ THƯƠNG MẠI VÀ XÂY LẮP HÙNG DŨNG | E19: 44993.625 | F19: 8000000 | G19: 8000000 | H19: 8000000 | I19: 8000000 | J19: =H19/G19 -> 1
A20: HĐ01/PMXD2023 | B20: Lập đơn giá | C20: Thực hiện tính toán và công bố chỉ số giá xây dựng tỉnh Thái Nguyên năm 2023 | E20: 45288.625 | F20: 250000000 | G20: 227272727 | H20: 45454545 | J20: =H20/G20 -> 0.2
A21: vv17/2023 | B21: SUMAC | C21: Công ty CP Bình Dương | E21: 45002.583 | F21: 2000000 | G21: 2000000 | H21: 2000000 | I21: 2000000 | J21: =H21/G21 -> 1
A22: vv18/2023 | B22: SUMAC | C22: Công Ty Cổ Phần Xây Dựng Và Dịch Vụ Nông Nghiệp Việt | E22: 45006.583 | F22: 6000000 | G22: 6000000 | H22: 6000000 | I22: 6000000 | J22: =H22/G22 -> 1
A23: vv19/2023 | B23: Escon 15 | C23: Công ty TNHH Cơ Điện & PCCC Tùng Bách | E23: 45009.583 | F23: 4000000 | G23: 4000000 | H23: 4000000 | I23: 4000000 | J23: =H23/G23 -> 1
A24: vv20/2023 | B24: Escon 15 | C24: Công ty TNHH MTV Nam Đồng | E24: 45014.583 | F24: 1500000 | G24: 1500000 | H24: 1500000 | I24: 1500000 | J24: =H24/G24 -> 1
A25: HĐ02/PMXD2023 | B25: Escon 15 | C25: Công An tỉnh Đắk Nông | E25: 45016.583 | F25: 16000000 | G25: 16000000 | H25: 16000000 | I25: 16000000 | J25: =H25/G25 -> 1
A26: vv21/2023 | B26: SUMAC | C26: Công ty TNHH thiết kế kiến trúc và xây dựng P.L.A Việt Nam | E26: 45016.583 | F26: 2000000 | G26: 2000000 | H26: 2000000 | I26: 2000000 | J26: =H26/G26 -> 1
A27: HĐ03/PMXD-CIC | B27: Lập đơn giá | C27: HỢP ĐỒNG TƯ VẤN LẬP BẢNG ĐƠN GIÁ NHÀ CỬA, VẬT KIẾN TRÚC VÀ NỘI THẤT TRÊN ĐỊA BÀN TỈNH NINH BÌNH | E27: 45202.583 | F27: 733120000 | G27: 678814815 | H27: 4.7517037e+08 | I27: 733120000 | J27: =H27/G27 -> 0.7
A28: Số :04HĐ/ SXD-CIC | B28: Lập đơn giá | C28: Tư vấn lập chỉ số giá xây dựng năm 2023 trên địa bàn tỉnh Bắc Kạn | E28: 45282.625 | F28: 299419000 | G28: 277239815 | H28: 1.2475792e+08 | I28: 299419000 | J28: =H28/G28 -> 0.45
A29: vv22/2023 | B29: Escon 15 | C29: Công ty TNHH MTV Hoàng Sang Kon tum | E29: 45051.583 | F29: 2500000 | G29: 2500000 | H29: 2500000 | I29: 2500000 | J29: =H29/G29 -> 1
A30: vv23/2023 | B30: Escon 15 | C30: Công ty TNHH Phát triển Hoàng Phát | E30: 45054.583 | F30: 1000000 | G30: 1000000 | H30: 1000000 | I30: 1000000 | J30: =H30/G30 -> 1
A31: Số :05HĐ/ SXD-CIC | B31: Lập đơn giá | C31: Tư vấn lập bộ đơn giá xây dựng công trình trên địa bàn tỉnh Hưng Yên | E31: 45233.583 | F31: 430000000 | G31: 398148148 | H31: 2.3888889e+08 | I31: 430000000 | J31: =H31/G31 -> 0.6
A32: Số :09/HĐTV | B32: Lập đơn giá | C32: Tư vấn Xác định giá ca máy và thiết bị thi công xây dựng trên địa bàn tỉnh Thái Nguyên năm 2023 | E32: 45250.625 | F32: 129000000 | G32: 117358920 | H32: 23471784 | I32: 126747000 | J32: =H32/G32 -> 0.2
... A34: vv24/2023 | B34: MCW | C34: Công Ty TNHH Tư Vấn-Xây Dựng Việt Kiến Tường | E34: 45068.583 | F34: 2000000 | G34: 5000000 | H34: 2000000 | I34: 5000000 | J34: =H34/G34 -> 0.4
A35: vv24/2023 | B35: Vinasas | C35: Công Ty TNHH Tư Vấn-Xây Dựng Việt Kiến Tường | F35: 3000000 | H35: 3000000 | J35: =H35/G35 -> #DIV/0!
A36: vv26/2023 | B36: SUMAC | C36: CÔNG TY TNHH XÂY DỰNG ĐẠI HÙNG LONG | E36: 45079.583 | F36: 2000000 | G36: 2000000 | H36: 2000000 | I36: 2000000 | J36: =H36/G36 -> 1
A37: vv27/2023 | B37: Escon 15 | C37: Công ty TNHH tư vấn và xây dựng Đại Nguyễn | E37: 45082.583 | F37: 4000000 | G37: 4000000 | H37: 4000000 | I37: 4000000 | J37: =H37/G37 -> 1
A38: vv28/2023 | B38: MDW | C38: Công ty TNHH MTV tư vấn Xây dựng Giao thông Lào Cai | E38: 45089.583 | F38: 1500000 | G38: 1500000 | H38: 1500000 | I38: 1500000 | J38: =H38/G38 -> 1
A39: vv29/2023 | B39: Escon 15 | C39: Nguyễn Công Khanh - Công ty Quảng Lợi | E39: 45282.625 | F39: 300000 | G39: 300000 | H39: 300000 | I39: 300000 | J39: =H39/G39 -> 1
A40: vv30/2023 | B40: Escon 15 | C40: Chi Nhánh Công Trình Viettel Lào Cai - Tổng Công Ty Cổ Phần Công Trình Viettel | E40: 45119.583 | F40: 8000000 | G40: 8000000 | H40: 8000000 | I40: 8000000 | J40: =H40/G40 -> 1
A41: vv31/2023 | B41: Escon 15 | C41: Trần Huy Quang | E41: 45282.625 | F41: 3800000 | G41: 3800000 | H41: 3800000 | I41: 3800000 | J41: =H41/G41 -> 1
...
