Workbook

Sheet Sản lượng ký kết
B1: 2024 | C1: BẢNG TỔNG HỢP SẢN LƯỢNG KÝ KẾT TỪ 01/01/2024 đến 03/03/2026
A2: STT | B2: Nội dung | C2: Tháng 1 | D2: Tháng 2 | E2: Tháng 3 | F2: Tháng 4 | G2: Tháng 5 | H2: Tháng 6 | I2: Tháng 7 | J2: Tháng 8 | K2: Tháng 9 | L2: Tháng 10 | M2: Tháng 11 | N2: Tháng 12 | O2: Tổng tháng | P2: Kế hoạch năm | Q2: Tỷ lệ % hoàn thành KH
A3: I | B3: Phần mềm xây dựng | C3: =sum(C4:C5) -> 11.8 | D3: =sum(D4:D5) -> 28.5 | E3: =sum(E4:E5) -> 21.5 | F3: =sum(F4:F5) -> 24.85 | G3: =sum(G4:G5) -> 27.15 | H3: =sum(H4:H5) -> 35.8 | I3: =sum(I4:I5) -> 918.514 | J3: =sum(J4:J5) -> 3.65 | ... N3: =sum(N4:N5) -> 47.55 | O3: =sum(C3:N3) -> 3935.414 | P3: =SUM(P4:P5) -> 3700 | Q3: =O3/P3 -> 1.0636254
B4: =hyperlink("https://docs.google.com/spreadsheets/d/17IwNqscaZ1nfXkCtx3V_0MEnuLIAYueeNI-uEmyeYNc/edit#gid=0","- Trung tâm PMXD") -> - Trung tâm PMXD | C4: 8.3 | D4: 21.5 | E4: 11 | F4: 7.5 | G4: 14.1 | H4: 6.3 | I4: 900.514 | J4: 2.3 | K4: 2266.8 | L4: 28.5 | M4: 507.7 | N4: 42.2 | O4: =sum(C4:N4) -> 3816.714 | P4: =IFERROR(__xludf.DUMMYFUNCTION("IMPORTRANGE(""1KQzbP_ErWqmWNgKzTyNE7LhnRtstc2D4GJ4FhZuHCZQ"", ""Kế hoạch 2024!b28"")"),3500.0) -> 3500 | Q4: =O4/P4 -> 1.0904897
B5: =hyperlink("https://docs.google.com/spreadsheets/d/1cdAyIuV3KTqwcGe6-vyb1X20cPPkDOOJQy9lqzxxIlg/edit#gid=0","- Chi nhánh") -> - Chi nhánh | C5: 3.5 | D5: 7 | E5: 10.5 | F5: 17.35 | G5: 13.05 | H5: 29.5 | I5: 18 | J5: 1.35 | K5: 11.1 | L5: 2 | M5: 0 | N5: 5.35 | O5: =sum(C5:N5) -> 118.7 | P5: 200 | Q5: =O5/P5 -> 0.5935
A6: II | B6: Phần mềm XD Nhập khẩu | C6: =SUM(C7:C8) -> 4015.2385 | D6: =SUM(D7:D8) -> 2556.0568 | E6: =SUM(E7:E8) -> 17648.75 | F6: =SUM(F7:F8) -> 8456.9691 | G6: =SUM(G7:G8) -> 14984.841 | H6: =SUM(H7:H8) -> 10850.095 | I6: =SUM(I7:I8) -> 6353.2795 | J6: =SUM(J7:J8) -> 5228.407 | ... N6: =SUM(N7:N8) -> 16032.659 | O6: =sum(C6:N6) -> 107486.7 | P6: =P8+P7 -> 76800 | Q6: =O6/P6 -> 1.3995663
B7: =hyperlink("https://docs.google.com/spreadsheets/d/1LGiIsREyb4-GdMHXfNtTTkfBPXxtYy4zobyDWot7xQA/edit#gid=0","- Trung tâm DCS") -> - Trung tâm DCS | C7: 1095.977 | D7: 1360.683 | E7: 14241.118 | F7: 2998.714 | G7: 4546.7313 | H7: 4516.385 | I7: 2936.0645 | J7: 2288.4363 | K7: 4704.18 | L7: 2021.1043 | M7: 2301.799 | N7: 11101.075 | O7: =sum(C7:N7) -> 54112.267 | P7: =IFERROR(__xludf.DUMMYFUNCTION("IMPORTRANGE(""1KQzbP_ErWqmWNgKzTyNE7LhnRtstc2D4GJ4FhZuHCZQ"", ""Kế hoạch 2024!c28"")"),35000.0) -> 35000 | Q7: =O7/P7 -> 1.5460648
B8: =hyperlink("https://docs.google.com/spreadsheets/d/1cdAyIuV3KTqwcGe6-vyb1X20cPPkDOOJQy9lqzxxIlg/edit#gid=0","- Chi nhánh") -> - Chi nhánh | C8: 2919.2615 | D8: 1195.3738 | E8: 3407.632 | F8: 5458.2551 | G8: 10438.11 | H8: 6333.7098 | I8: 3417.215 | J8: 2939.9707 | K8: 3357.675 | L8: 7956.75 | M8: 1018.8916 | N8: 4931.5841 | O8: =sum(C8:N8) -> 53374.428 | P8: =IFERROR(__xludf.DUMMYFUNCTION("IMPORTRANGE(""1KQzbP_ErWqmWNgKzTyNE7LhnRtstc2D4GJ4FhZuHCZQ"", ""Kế hoạch 2024!D28"")-P5"),41800.0) -> 41800 | Q8: =O8/P8 -> 1.2769002
A9: III | B9: =hyperlink("https://docs.google.com/spreadsheets/d/17WRbCuo0DVepxTRtwozyxF08Zfve8uQViqsT2QSth8I/edit#gid=0","Trung tâm STC") -> Trung tâm STC | C9: 815.639 | D9: 0 | E9: 361.175 | F9: 1242.0238 | G9: 942.34 | H9: 1709.3948 | I9: 1392.7181 | J9: 616.385 | K9: 5115.6608 | L9: 3077.41 | M9: 447.079 | N9: 12900.9 | O9: =sum(C9:N9) -> 28620.725 | P9: =IFERROR(__xludf.DUMMYFUNCTION("IMPORTRANGE(""1KQzbP_ErWqmWNgKzTyNE7LhnRtstc2D4GJ4FhZuHCZQ"", ""Kế hoạch 2024!e28"")"),31000.0) -> 31000 | Q9: =O9/P9 -> 0.92324921
A10: VI | B10: =hyperlink("https://docs.google.com/spreadsheets/d/1yTBWEM4qeN7cMsdZosoLoINbcnjIbiM09amCGs1O-XI/edit#gid=0","Trung tâm TVDA") -> Trung tâm TVDA | C10: 0 | D10: 0 | E10: 234 | F10: 234 | G10: 234 | H10: 6.6 | I10: 899.251 | J10: 0 | K10: 494.27 | L10: 741.871 | M10: 93 | N10: 25.815408 | O10: =sum(C10:N10) -> 2962.8074 | P10: =IFERROR(__xludf.DUMMYFUNCTION("IMPORTRANGE(""1KQzbP_ErWqmWNgKzTyNE7LhnRtstc2D4GJ4FhZuHCZQ"", ""Kế hoạch 2024!f28"")"),1500.0) -> 1500 | Q10: =O10/P10 -> 1.9752049
A11: V | B11: =hyperlink("https://docs.google.com/spreadsheets/d/1RHfET1y4R66vHlp6uC32W0Nz_3ubpd5g4n5dZxWkyaw/edit#gid=0","Trung tâm TVTK") -> Trung tâm TVTK | C11: 0 | O11: =sum(C11:N11) -> 0 | P11: =IFERROR(__xludf.DUMMYFUNCTION("IMPORTRANGE(""1KQzbP_ErWqmWNgKzTyNE7LhnRtstc2D4GJ4FhZuHCZQ"", ""Kế hoạch 2024!g28"")"),3000.0) -> 3000 | Q11: =O11/P11 -> 0
A12: VI | B12: =hyperlink("https://docs.google.com/spreadsheets/d/1NiLWC2P93vOYhLmUW_D3xnNV-9HJraVhA0DrW4_m5jo/edit#gid=0","Trung tâm TMB") -> Trung tâm TMB | C12: 0 | E12: 81.3 | F12: 170.43 | G12: 196.6 | H12: 1370.11 | I12: 116.84 | J12: 0 | K12: 237.25 | L12: 905.269 | M12: 0 | N12: 435.67 | O12: =sum(C12:N12) -> 3513.469 | P12: =IFERROR(__xludf.DUMMYFUNCTION("IMPORTRANGE(""1KQzbP_ErWqmWNgKzTyNE7LhnRtstc2D4GJ4FhZuHCZQ"", ""Kế hoạch 2024!h28"")"),4000.0) -> 4000 | Q12: =O12/P12 -> 0.87836725
A13: VII | B13: =hyperlink("https://docs.google.com/spreadsheets/d/1qGsXBQA7UK_C9LOomu1EW4PbhsRPWpCf9o9ByaiP77Y/edit#gid=0","Trung tâm BIM") -> Trung tâm BIM | C13: 0 | D13: 8889.9392 | E13: 270 | F13: 999.8821 | G13: 703.503 | H13: 0 | I13: 964.27996 | J13: 615 | K13: 8165.8772 | L13: 1030.6 | M13: 0 | N13: 195.10778 | O13: =sum(C13:N13) -> 21834.189 | P13: =IFERROR(__xludf.DUMMYFUNCTION("IMPORTRANGE(""1KQzbP_ErWqmWNgKzTyNE7LhnRtstc2D4GJ4FhZuHCZQ"", ""Kế hoạch 2024!i28"")"),15000.0) -> 15000 | Q13: =O13/P13 -> 1.4556126
A14: VIII | B14: =hyperlink("https://docs.google.com/spreadsheets/d/1TGKe-aBIfi6jlUkNz8gWl8ld-iWWsJOQj3t5hybOWtQ/edit#gid=0","Các lĩnh vực khác") -> Các lĩnh vực khác | C14: 373.096 | O14: =sum(C14:N14) -> 373.096 | P14: 0
A15: IX | B15: Tổng chung toàn CT | C15: =SUM(C16:C17) -> 5215.7735 | D15: =SUM(D16:D17) -> 11474.496 | E15: =SUM(E16:E17) -> 18616.725 | F15: =SUM(F16:F17) -> 11128.155 | G15: =SUM(G16:G17) -> 17088.434 | H15: =SUM(H16:H17) -> 13972 | I15: =SUM(I16:I17) -> 10644.883 | J15: =SUM(J16:J17) -> 6463.442 | ... N15: =SUM(N16:N17) -> 29637.702 | O15: =sum(C15:N15) -> 168726.4 | P15: =P17+P16 -> 135000 | Q15: =O15/P15 -> 1.2498252
B16: CIC Hà Nội | C16: =C4+C7+C9+C10+C11+C12+C13+C14 -> 2293.012 | D16: =D4+D7+D9+D10+D11+D12+D13+D14 -> 10272.122 | E16: =E4+E7+E9+E10+E11+E12+E13+E14 -> 15198.593 | F16: =F4+F7+F9+F10+F11+F12+F13+F14 -> 5652.5499 | G16: =G4+G7+G9+G10+G11+G12+G13+G14 -> 6637.2743 | H16: =H4+H7+H9+H10+H11+H12+H13+H14 -> 7608.7898 | I16: =I4+I7+I9+I10+I11+I12+I13+I14 -> 7209.6676 | J16: =J4+J7+J9+J10+J11+J12+J13+J14 -> 3522.1213 | ... N16: =N4+N7+N9+N10+N11+N12+N13+N14 -> 24700.768 | O16: =SUM(C16:N16) -> 115233.27 | P16: =P4+P7+P9+P10+P11+P12+P13+P14 -> 93000 | Q16: =O16/P16 -> 1.2390674
B17: CIC Hồ Chí Minh | C17: =C5+C8 -> 2922.7615 | D17: =D5+D8 -> 1202.3738 | E17: =E5+E8 -> 3418.132 | F17: =F5+F8 -> 5475.6051 | G17: =G5+G8 -> 10451.159 | H17: =H5+H8 -> 6363.2098 | I17: =I5+I8 -> 3435.215 | J17: =J5+J8 -> 2941.3207 | ... N17: =N5+N8 -> 4936.9341 | O17: =SUM(C17:N17) -> 53493.128 | P17: =P5+P8 -> 42000 | Q17: =O17/P17 -> 1.2736459
B18: Toàn công ty 2023 | C18: =IFERROR(__xludf.DUMMYFUNCTION("IMPORTRANGE(""1mgk5_08R7QPyVWFUtyotwoussHVEv6Lz8ls-NcbSu3U"", ""Sản lượng ký kết!C14"")"),11490.2704) -> 11490.27 | D18: =IFERROR(__xludf.DUMMYFUNCTION("IMPORTRANGE(""1mgk5_08R7QPyVWFUtyotwoussHVEv6Lz8ls-NcbSu3U"", ""Sản lượng ký kết!D14"")"),5699.8243999999995) -> 5699.8244 | E18: =IFERROR(__xludf.DUMMYFUNCTION("IMPORTRANGE(""1mgk5_08R7QPyVWFUtyotwoussHVEv6Lz8ls-NcbSu3U"", ""Sản lượng ký kết!E14"")"),20438.277033) -> 20438.277 | F18: =IFERROR(__xludf.DUMMYFUNCTION("IMPORTRANGE(""1mgk5_08R7QPyVWFUtyotwoussHVEv6Lz8ls-NcbSu3U"", ""Sản lượng ký kết!f14"")"),5046.9266) -> 5046.9266 | G18: =IFERROR(__xludf.DUMMYFUNCTION("IMPORTRANGE(""1mgk5_08R7QPyVWFUtyotwoussHVEv6Lz8ls-NcbSu3U"", ""Sản lượng ký kết!g14"")"),14038.05417) -> 14038.054 | H18: =IFERROR(__xludf.DUMMYFUNCTION("IMPORTRANGE(""1mgk5_08R7QPyVWFUtyotwoussHVEv6Lz8ls-NcbSu3U"", ""Sản lượng ký kết!h14"")"),8081.563340000001) -> 8081.5633 | I18: =IFERROR(__xludf.DUMMYFUNCTION("IMPORTRANGE(""1mgk5_08R7QPyVWFUtyotwoussHVEv6Lz8ls-NcbSu3U"", ""Sản lượng ký kết!i14"")"),5860.22579) -> 5860.2258 | J18: =IFERROR(__xludf.DUMMYFUNCTION("IMPORTRANGE(""1mgk5_08R7QPyVWFUtyotwoussHVEv6Lz8ls-NcbSu3U"", ""Sản lượng ký kết!j14"")"),12673.0947) -> 12673.095 | K18: =IFERROR(__xludf.DUMMYFUNCTION("IMPORTRANGE(""1mgk5_08R7QPyVWFUtyotwoussHVEv6Lz8ls-NcbSu3U"", ""Sản lượng ký kết!k14"")"),20165.6312) -> 20165.631 | L18: =IFERROR(__xludf.DUMMYFUNCTION("IMPORTRANGE(""1mgk5_08R7QPyVWFUtyotwoussHVEv6Lz8ls-NcbSu3U"", ""Sản lượng ký kết!l14"")"),7385.805200000001) -> 7385.8052 | M18: =IFERROR(__xludf.DUMMYFUNCTION("IMPORTRANGE(""1mgk5_08R7QPyVWFUtyotwoussHVEv6Lz8ls-NcbSu3U"", ""Sản lượng ký kết!m14"")"),14830.312137777777) -> 14830.312 | N18: =IFERROR(__xludf.DUMMYFUNCTION("IMPORTRANGE(""1mgk5_08R7QPyVWFUtyotwoussHVEv6Lz8ls-NcbSu3U"", ""Sản lượng ký kết!n14"")"),13046.15998) -> 13046.16 | O18: =SUM(C18:N18) -> 138756.14
B19: So sánh 2024/2023 | C19: =C15/C18 -> 0.45392957 | D19: =D15/D18 -> 2.0131315 | E19: =E15/E18 -> 0.91087546 | F19: =F15/F18 -> 2.204937 | G19: =G15/G18 -> 1.2172936 | H19: =H15/H18 -> 1.7288734 | I19: =I15/I18 -> 1.8164629 | J19: =J15/J18 -> 0.51001292 | ... O19: =O15/O18 -> 1.2159922
B20: SS cùng kỳ năm ngoái | D20: =sum($C15:D15)/sum($C18:D18) -> 0.97092364 | E20: =sum($C15:E15)/sum($C18:E18) -> 0.93830779 | F20: =sum($C15:F15)/sum($C18:F18) -> 1.0881037 | G20: =sum($C15:G15)/sum($C18:G18) -> 1.1200816 | H20: =sum($C15:H15)/sum($C18:H18) -> 1.1960133 | I20: =sum($C15:I15)/sum($C18:I18) -> 1.2474742 | J20: =sum($C15:J15)/sum($C18:J18) -> 1.1353163 | K20: =sum($C15:K15)/sum($C18:K18) -> 1.1494084 | ... N20: =sum($C15:N15)/sum($C18:N18) -> 1.2159922 | O20: Kế hoạch # | P20: 90000 | Q20: =O15/P20 -> 1.8747377

Sheet Tổng hợp Doanh thu
B1: ='Sản lượng ký kết'!B1 -> 2024 | C1: BẢNG TỔNG HỢP DOANH THU TỪ 01/01/2024 đến 03/03/2026
A2: STT | B2: Nội dung | C2: Tháng 1 | D2: Tháng 2 | E2: Tháng 3 | F2: Tháng 4 | G2: Tháng 5 | H2: Tháng 6 | I2: Tháng 7 | J2: Tháng 8 | K2: Tháng 9 | L2: Tháng 10 | M2: Tháng 11 | N2: Tháng 12 | O2: Tổng tháng | P2: Kế hoạch năm | Q2: Tỷ lệ % hoàn thành KH
A3: I | B3: Phần mềm xây dựng | C3: =sum(C4:C5) -> 3.5 | D3: =sum(D4:D5) -> 28.5 | E3: =sum(E4:E5) -> 18.5 | F3: =sum(F4:F5) -> 21.35 | G3: =sum(G4:G5) -> 18.55 | H3: =sum(H4:H5) -> 40.5 | I3: =sum(I4:I5) -> 37.5 | J3: =sum(J4:J5) -> 15.55 | ... N3: =sum(N4:N5) -> 1880.1241 | O3: =sum(C3:N3) -> 2188.6741 | P3: =SUM(P4:P5) -> 3460 | Q3: =O3/P3 -> 0.63256476
B4: =hyperlink("https://docs.google.com/spreadsheets/d/17IwNqscaZ1nfXkCtx3V_0MEnuLIAYueeNI-uEmyeYNc/edit#gid=0","- Trung tâm PMXD") -> - Trung tâm PMXD | D4: 21.5 | E4: 8 | F4: 4 | G4: 10.5 | H4: 6 | I4: 19.5 | J4: 12.7 | K4: 11.1 | L4: 44.2 | M4: 57.7 | N4: 1876.1241 | O4: =sum(C4:N4) -> 2071.3241 | P4: =IFERROR(__xludf.DUMMYFUNCTION("IMPORTRANGE(""1KQzbP_ErWqmWNgKzTyNE7LhnRtstc2D4GJ4FhZuHCZQ"", ""Kế hoạch 2024!b60"")"),3260.0) -> 3260 | Q4: =O4/P4 -> 0.63537548
B5: =hyperlink("https://docs.google.com/spreadsheets/d/1cdAyIuV3KTqwcGe6-vyb1X20cPPkDOOJQy9lqzxxIlg/edit#gid=0","- Chi nhánh") -> - Chi nhánh | C5: 3.5 | D5: 7 | E5: 10.5 | F5: 17.35 | G5: 8.05 | H5: 34.5 | I5: 18 | J5: 2.85 | K5: 9.6 | L5: 2 | N5: 4 | O5: =sum(C5:N5) -> 117.35 | P5: 200 | Q5: =O5/P5 -> 0.58675
A6: II | B6: Phần mềm XD Nhập khẩu | C6: =SUM(C7:C8) -> 6004.0681 | D6: =SUM(D7:D8) -> 2605.2103 | E6: =SUM(E7:E8) -> 8152.7581 | F6: =SUM(F7:F8) -> 15700.78 | G6: =SUM(G7:G8) -> 8197.1584 | H6: =SUM(H7:H8) -> 14530.089 | I6: =SUM(I7:I8) -> 7326.6007 | J6: =SUM(J7:J8) -> 7928.5016 | ... N6: =SUM(N7:N8) -> 10196.033 | O6: =sum(C6:N6) -> 106472.5 | P6: =P8+P7 -> 71000 | Q6: =O6/P6 -> 1.4996127
B7: =hyperlink("https://docs.google.com/spreadsheets/d/1LGiIsREyb4-GdMHXfNtTTkfBPXxtYy4zobyDWot7xQA/edit#gid=0","- Trung tâm DCS") -> - Trung tâm DCS | C7: 4055.8457 | D7: 1938.6067 | E7: 4685.52 | F7: 10207.464 | G7: 4703.379 | H7: 5115.0249 | I7: 1198.6969 | J7: 4052.7049 | K7: 5153.245 | L7: 4352.6928 | M7: 2080.7103 | N7: 6086.3841 | O7: =sum(C7:N7) -> 53630.274 | P7: =IFERROR(__xludf.DUMMYFUNCTION("IMPORTRANGE(""1KQzbP_ErWqmWNgKzTyNE7LhnRtstc2D4GJ4FhZuHCZQ"", ""Kế hoạch 2024!c60"")"),32200.0) -> 32200 | Q7: =O7/P7 -> 1.6655365
B8: =hyperlink("https://docs.google.com/spreadsheets/d/1cdAyIuV3KTqwcGe6-vyb1X20cPPkDOOJQy9lqzxxIlg/edit#gid=0","- Chi nhánh") -> - Chi nhánh | C8: 1948.2224 | D8: 666.6035 | E8: 3467.2382 | F8: 5493.3158 | G8: 3493.7794 | H8: 9415.064 | I8: 6127.9038 | J8: 3875.7967 | K8: 3097.8059 | L8: 8572.8115 | M8: 2574.0371 | N8: 4109.6494 | O8: =sum(C8:N8) -> 52842.228 | P8: =IFERROR(__xludf.DUMMYFUNCTION("IMPORTRANGE(""1KQzbP_ErWqmWNgKzTyNE7LhnRtstc2D4GJ4FhZuHCZQ"", ""Kế hoạch 2024!D60"")-P5"),38800.0) -> 38800 | Q8: =O8/P8 -> 1.3619131
A9: III | B9: =hyperlink("https://docs.google.com/spreadsheets/d/17WRbCuo0DVepxTRtwozyxF08Zfve8uQViqsT2QSth8I/edit#gid=0","Trung tâm STC") -> Trung tâm STC | C9: 1166.25 | E9: 1507.579 | F9: 606.865 | G9: 79.4 | H9: 3460.758 | I9: 1386.2338 | J9: 405.32944 | K9: 3247.761 | L9: 2677.3677 | M9: 1169.22 | N9: 2558.9727 | O9: =sum(C9:N9) -> 18265.737 | P9: =IFERROR(__xludf.DUMMYFUNCTION("IMPORTRANGE(""1KQzbP_ErWqmWNgKzTyNE7LhnRtstc2D4GJ4FhZuHCZQ"", ""Kế hoạch 2024!e60"")"),29000.0) -> 29000 | Q9: =O9/P9 -> 0.62985299
A10: VI | B10: =hyperlink("https://docs.google.com/spreadsheets/d/1yTBWEM4qeN7cMsdZosoLoINbcnjIbiM09amCGs1O-XI/edit#gid=0","Trung tâm TVDA") -> Trung tâm TVDA | L10: 6 | M10: 26.361111 | N10: 1996.7878 | O10: =sum(C10:N10) -> 2029.1489 | P10: =IFERROR(__xludf.DUMMYFUNCTION("IMPORTRANGE(""1KQzbP_ErWqmWNgKzTyNE7LhnRtstc2D4GJ4FhZuHCZQ"", ""Kế hoạch 2024!f60"")"),1500.0) -> 1500 | Q10: =O10/P10 -> 1.3527659
A11: V | B11: =hyperlink("https://docs.google.com/spreadsheets/d/1RHfET1y4R66vHlp6uC32W0Nz_3ubpd5g4n5dZxWkyaw/edit#gid=0","Trung tâm TVTK") -> Trung tâm TVTK | C11: 147.46718 | H11: 147.46718 | N11: 147.46718 | O11: =sum(C11:N11) -> 442.40155 | P11: =IFERROR(__xludf.DUMMYFUNCTION("IMPORTRANGE(""1KQzbP_ErWqmWNgKzTyNE7LhnRtstc2D4GJ4FhZuHCZQ"", ""Kế hoạch 2024!g60"")"),2500.0) -> 2500 | Q11: =O11/P11 -> 0.17696062
A12: VI | B12: =hyperlink("https://docs.google.com/spreadsheets/d/1NiLWC2P93vOYhLmUW_D3xnNV-9HJraVhA0DrW4_m5jo/edit#gid=0","Trung tâm TMB") -> Trung tâm TMB | G12: 170.43 | H12: 80.5 | I12: 264.905 | J12: 144.6 | N12: 336.505 | O12: =sum(C12:N12) -> 996.94 | P12: =IFERROR(__xludf.DUMMYFUNCTION("IMPORTRANGE(""1KQzbP_ErWqmWNgKzTyNE7LhnRtstc2D4GJ4FhZuHCZQ"", ""Kế hoạch 2024!h60"")"),3500.0) -> 3500 | Q12: =O12/P12 -> 0.28484
A13: VII | B13: =hyperlink("https://docs.google.com/spreadsheets/d/1qGsXBQA7UK_C9LOomu1EW4PbhsRPWpCf9o9ByaiP77Y/edit#gid=0","Trung tâm BIM") -> Trung tâm BIM | E13: 405.38608 | F13: 50 | G13: 1256.4392 | H13: 10.909091 | I13: 97.243 | J13: 1350 | K13: 1710 | N13: 3520.5834 | O13: =sum(C13:N13) -> 8400.5608 | P13: =IFERROR(__xludf.DUMMYFUNCTION("IMPORTRANGE(""1KQzbP_ErWqmWNgKzTyNE7LhnRtstc2D4GJ4FhZuHCZQ"", ""Kế hoạch 2024!i60"")"),12000.0) -> 12000 | Q13: =O13/P13 -> 0.70004673
A14: VIII | B14: =hyperlink("https://docs.google.com/spreadsheets/d/1TGKe-aBIfi6jlUkNz8gWl8ld-iWWsJOQj3t5hybOWtQ/edit#gid=0","Các lĩnh vực khác") -> Các lĩnh vực khác | O14: 0 | P14: 0
A15: IX | B15: Tổng chung toàn CT | C15: =SUM(C16:C17) -> 7321.2853 | D15: =SUM(D16:D17) -> 2633.7103 | E15: =SUM(E16:E17) -> 10084.223 | F15: =SUM(F16:F17) -> 16378.995 | G15: =SUM(G16:G17) -> 9721.9776 | H15: =SUM(H16:H17) -> 18270.223 | I15: =SUM(I16:I17) -> 9112.4825 | J15: =SUM(J16:J17) -> 9843.981 | ... N15: =SUM(N16:N17) -> 20636.474 | O15: =sum(C15:N15) -> 138795.96 | P15: =P17+P16 -> 122960 | Q15: =O15/P15 -> 1.1287896
B16: CIC Hà Nội | C16: =C4+C7+C9+C10+C11+C12+C13+C14 -> 5369.5629 | D16: =D4+D7+D9+D10+D11+D12+D13+D14 -> 1960.1067 | E16: =E4+E7+E9+E10+E11+E12+E13+E14 -> 6606.4851 | F16: =F4+F7+F9+F10+F11+F12+F13+F14 -> 10868.329 | G16: =G4+G7+G9+G10+G11+G12+G13+G14 -> 6220.1482 | H16: =H4+H7+H9+H10+H11+H12+H13+H14 -> 8820.6592 | I16: =I4+I7+I9+I10+I11+I12+I13+I14 -> 2966.5787 | J16: =J4+J7+J9+J10+J11+J12+J13+J14 -> 5965.3343 | ... N16: =N4+N7+N9+N10+N11+N12+N13+N14 -> 16522.824 | O16: =SUM(C16:N16) -> 85836.386 | P16: =P4+P7+P9+P10+P11+P12+P13+P14 -> 83960 | Q16: =O16/P16 -> 1.0223486
B17: CIC Hồ Chí Minh | C17: =C5+C8 -> 1951.7224 | D17: =D5+D8 -> 673.6035 | E17: =E5+E8 -> 3477.7382 | F17: =F5+F8 -> 5510.6659 | G17: =G5+G8 -> 3501.8294 | H17: =H5+H8 -> 9449.564 | I17: =I5+I8 -> 6145.9038 | J17: =J5+J8 -> 3878.6467 | ... N17: =N5+N8 -> 4113.6494 | O17: =SUM(C17:N17) -> 52959.578 | P17: =P5+P8 -> 39000 | Q17: =O17/P17 -> 1.3579379
B18: Toàn công ty 2023 | C18: =IFERROR(__xludf.DUMMYFUNCTION("IMPORTRANGE(""1mgk5_08R7QPyVWFUtyotwoussHVEv6Lz8ls-NcbSu3U"", ""Tổng hợp doanh thu!C14"")"),1201.9737) -> 1201.9737 | D18: =IFERROR(__xludf.DUMMYFUNCTION("IMPORTRANGE(""1mgk5_08R7QPyVWFUtyotwoussHVEv6Lz8ls-NcbSu3U"", ""Tổng hợp doanh thu!D14"")"),5406.2467) -> 5406.2467 | E18: =IFERROR(__xludf.DUMMYFUNCTION("IMPORTRANGE(""1mgk5_08R7QPyVWFUtyotwoussHVEv6Lz8ls-NcbSu3U"", ""Tổng hợp doanh thu!E14"")"),5204.3992) -> 5204.3992 | F18: =IFERROR(__xludf.DUMMYFUNCTION("IMPORTRANGE(""1mgk5_08R7QPyVWFUtyotwoussHVEv6Lz8ls-NcbSu3U"", ""Tổng hợp doanh thu!F14"")"),5106.948555) -> 5106.9486 | G18: =IFERROR(__xludf.DUMMYFUNCTION("IMPORTRANGE(""1mgk5_08R7QPyVWFUtyotwoussHVEv6Lz8ls-NcbSu3U"", ""Tổng hợp doanh thu!G14"")"),20267.64702) -> 20267.647 | H18: =IFERROR(__xludf.DUMMYFUNCTION("IMPORTRANGE(""1mgk5_08R7QPyVWFUtyotwoussHVEv6Lz8ls-NcbSu3U"", ""Tổng hợp doanh thu!H14"")"),6586.827669) -> 6586.8277 | I18: =IFERROR(__xludf.DUMMYFUNCTION("IMPORTRANGE(""1mgk5_08R7QPyVWFUtyotwoussHVEv6Lz8ls-NcbSu3U"", ""Tổng hợp doanh thu!I14"")"),6360.192822000001) -> 6360.1928 | J18: =IFERROR(__xludf.DUMMYFUNCTION("IMPORTRANGE(""1mgk5_08R7QPyVWFUtyotwoussHVEv6Lz8ls-NcbSu3U"", ""Tổng hợp doanh thu!J14"")"),6236.086588) -> 6236.0866 | K18: =IFERROR(__xludf.DUMMYFUNCTION("IMPORTRANGE(""1mgk5_08R7QPyVWFUtyotwoussHVEv6Lz8ls-NcbSu3U"", ""Tổng hợp doanh thu!K14"")"),10740.193741000001) -> 10740.194 | L18: =IFERROR(__xludf.DUMMYFUNCTION("IMPORTRANGE(""1mgk5_08R7QPyVWFUtyotwoussHVEv6Lz8ls-NcbSu3U"", ""Tổng hợp doanh thu!L14"")"),13410.885968999999) -> 13410.886 | M18: =IFERROR(__xludf.DUMMYFUNCTION("IMPORTRANGE(""1mgk5_08R7QPyVWFUtyotwoussHVEv6Lz8ls-NcbSu3U"", ""Tổng hợp doanh thu!M14"")"),14566.623877) -> 14566.624 | N18: =IFERROR(__xludf.DUMMYFUNCTION("IMPORTRANGE(""1mgk5_08R7QPyVWFUtyotwoussHVEv6Lz8ls-NcbSu3U"", ""Tổng hợp doanh thu!N14"")"),22215.175305999997) -> 22215.175 | O18: =SUM(C18:N18) -> 117303.2
B19: So sánh 2024/2023 | C19: =C15/C18 -> 6.0910528 | D19: =D15/D18 -> 0.48716057 | E19: =E15/E18 -> 1.9376345 | F19: =F15/F18 -> 3.2071979 | G19: =G15/G18 -> 0.47967964 | H19: =H15/H18 -> 2.7737515 | I19: =I15/I18 -> 1.4327368 | J19: =J15/J18 -> 1.578551 | ... O19: =O15/O18 -> 1.183224
B20: SS cùng kỳ năm ngoái | D20: =sum($C15:D15)/sum($C18:D18) -> 1.5064563 | E20: =sum($C15:E15)/sum($C18:E18) -> 1.6964246 | F20: =sum($C15:F15)/sum($C18:F18) -> 2.1524316 | G20: =sum($C15:G15)/sum($C18:G18) -> 1.2407541 | H20: =sum($C15:H15)/sum($C18:H18) -> 1.4714294 | I20: =sum($C15:I15)/sum($C18:I18) -> 1.4665208 | J20: =sum($C15:J15)/sum($C18:J18) -> 1.4789143 | K20: =sum($C15:K15)/sum($C18:K18) -> 1.4393629 | ... N20: =sum($C15:N15)/sum($C18:N18) -> 1.183224 | O20: Kế hoạch # | P20: 80000 | Q20: =O15/P20 -> 1.7349496

Sheet Lợi nhuận gộp quản trị
B1: ='Sản lượng ký kết'!B1 -> 2024 | C1: BẢNG TỔNG HỢP LỢI NHUẬN GỘP QUẢN TRỊ TỪ 01/01/2024 đến 03/03/2026
A2: STT | B2: Nội dung | C2: Tháng 1 | D2: Tháng 2 | E2: Tháng 3 | F2: Tháng 4 | G2: Tháng 5 | H2: Tháng 6 | I2: Tháng 7 | J2: Tháng 8 | K2: Tháng 9 | L2: Tháng 10 | M2: Tháng 11 | N2: Tháng 12 | O2: Tổng tháng | P2: Kế hoạch năm | Q2: Tỷ lệ % hoàn thành KH
A3: I | B3: Phần mềm xây dựng | C3: =sum(C4:C5) -> 1.925 | D3: =sum(D4:D5) -> 25.35 | E3: =sum(E4:E5) -> 16.775 | F3: =sum(F4:F5) -> 17.0425 | G3: =sum(G4:G5) -> 16.4025 | H3: =sum(H4:H5) -> 18.125 | I3: =sum(I4:I5) -> 441.94111 | J3: =sum(J4:J5) -> 3.0425 | ... N3: =sum(N4:N5) -> 45.1425 | O3: =sum(C3:N3) -> 1613.1807 | P3: =SUM(P4:P5) -> 2180 | Q3: =O3/P3 -> 0.73999117
B4: =hyperlink("https://docs.google.com/spreadsheets/d/17IwNqscaZ1nfXkCtx3V_0MEnuLIAYueeNI-uEmyeYNc/edit#gid=0","- Trung tâm PMXD") -> - Trung tâm PMXD | C4: 0 | D4: 21.5 | E4: 11 | F4: 7.5 | G4: 12.8 | H4: 6.3 | I4: 434.24111 | J4: 2.3 | K4: 686.82963 | L4: 27.7 | M4: 305.7 | N4: 42.2 | O4: =sum(C4:N4) -> 1558.0707 | P4: =IFERROR(__xludf.DUMMYFUNCTION("IMPORTRANGE(""1KQzbP_ErWqmWNgKzTyNE7LhnRtstc2D4GJ4FhZuHCZQ"", ""Kế hoạch 2024!b93"")"),2000.0) -> 2000 | Q4: =O4/P4 -> 0.77903537
B5: =hyperlink("https://docs.google.com/spreadsheets/d/1cdAyIuV3KTqwcGe6-vyb1X20cPPkDOOJQy9lqzxxIlg/edit#gid=0","- Chi nhánh") -> - Chi nhánh | C5: 1.925 | D5: 3.85 | E5: 5.775 | F5: 9.5425 | G5: 3.6025 | H5: 11.825 | I5: 7.7 | J5: 0.7425 | K5: 6.105 | L5: 1.1 | M5: 0 | N5: 2.9425 | O5: =sum(C5:N5) -> 55.11 | P5: 180 | Q5: =O5/P5 -> 0.30616667
A6: II | B6: Phần mềm XD Nhập khẩu | C6: =SUM(C7:C8) -> 484.43652 | D6: =SUM(D7:D8) -> 472.36472 | E6: =SUM(E7:E8) -> 2813.2823 | F6: =SUM(F7:F8) -> 1272.7799 | G6: =SUM(G7:G8) -> 2673.4447 | H6: =SUM(H7:H8) -> 1819.2954 | I6: =SUM(I7:I8) -> 996.79547 | J6: =SUM(J7:J8) -> 813.49327 | ... N6: =SUM(N7:N8) -> 2505.4408 | O6: =sum(C6:N6) -> 18275.39 | P6: =P8+P7 -> 13670 | Q6: =O6/P6 -> 1.3368976
B7: =hyperlink("https://docs.google.com/spreadsheets/d/1LGiIsREyb4-GdMHXfNtTTkfBPXxtYy4zobyDWot7xQA/edit#gid=0","- Trung tâm DCS") -> - Trung tâm DCS | C7: 142.1809 | D7: 299.27776 | E7: 2046.9026 | F7: 446.21797 | G7: 1221.2011 | H7: 797.06142 | I7: 527.73748 | J7: 419.84753 | K7: 963.98807 | L7: 467.51358 | M7: 225.85156 | N7: 1894.3342 | O7: =sum(C7:N7) -> 9452.1142 | P7: =IFERROR(__xludf.DUMMYFUNCTION("IMPORTRANGE(""1KQzbP_ErWqmWNgKzTyNE7LhnRtstc2D4GJ4FhZuHCZQ"", ""Kế hoạch 2024!c93"")"),6200.0) -> 6200 | Q7: =O7/P7 -> 1.5245345
B8: =hyperlink("https://docs.google.com/spreadsheets/d/1cdAyIuV3KTqwcGe6-vyb1X20cPPkDOOJQy9lqzxxIlg/edit#gid=0","- Chi nhánh") -> - Chi nhánh | C8: 342.25561 | D8: 173.08695 | E8: 766.37971 | F8: 826.56192 | G8: 1452.2436 | H8: 1022.234 | I8: 469.05799 | J8: 393.64575 | K8: 631.54558 | L8: 1986.9345 | M8: 148.22349 | N8: 611.10657 | O8: =sum(C8:N8) -> 8823.2756 | P8: =IFERROR(__xludf.DUMMYFUNCTION("IMPORTRANGE(""1KQzbP_ErWqmWNgKzTyNE7LhnRtstc2D4GJ4FhZuHCZQ"", ""Kế hoạch 2024!D93"")-P5"),7470.0) -> 7470 | Q8: =O8/P8 -> 1.1811614
A9: III | B9: =hyperlink("https://docs.google.com/spreadsheets/d/17WRbCuo0DVepxTRtwozyxF08Zfve8uQViqsT2QSth8I/edit#gid=0","Trung tâm STC") -> Trung tâm STC | C9: 213.16044 | D9: 0 | E9: 69.340416 | F9: 238.59745 | G9: 115.04018 | H9: 278.87778 | I9: 348.77171 | J9: 141.54255 | K9: 935.18892 | L9: 612.88805 | M9: 148.99907 | N9: 318.97064 | O9: =sum(C9:N9) -> 3421.3772 | P9: =IFERROR(__xludf.DUMMYFUNCTION("IMPORTRANGE(""1KQzbP_ErWqmWNgKzTyNE7LhnRtstc2D4GJ4FhZuHCZQ"", ""Kế hoạch 2024!e93"")"),4300.0) -> 4300 | Q9: =O9/P9 -> 0.79566912
A10: VI | B10: =hyperlink("https://docs.google.com/spreadsheets/d/1yTBWEM4qeN7cMsdZosoLoINbcnjIbiM09amCGs1O-XI/edit#gid=0","Trung tâm TVDA") -> Trung tâm TVDA | C10: 0 | D10: 0 | E10: 0 | F10: 0 | G10: 0 | H10: 6 | I10: 382.81222 | J10: 0 | K10: 236.93907 | L10: 276.26044 | M10: 50.971111 | N10: 23.903156 | O10: =sum(C10:N10) -> 976.88599 | P10: =IFERROR(__xludf.DUMMYFUNCTION("IMPORTRANGE(""1KQzbP_ErWqmWNgKzTyNE7LhnRtstc2D4GJ4FhZuHCZQ"", ""Kế hoạch 2024!f93"")"),1050.0) -> 1050 | Q10: =O10/P10 -> 0.93036761
A11: V | B11: =hyperlink("https://docs.google.com/spreadsheets/d/1RHfET1y4R66vHlp6uC32W0Nz_3ubpd5g4n5dZxWkyaw/edit#gid=0","Trung tâm TVTK") -> Trung tâm TVTK | C11: 0 | O11: =sum(C11:N11) -> 0 | P11: =IFERROR(__xludf.DUMMYFUNCTION("IMPORTRANGE(""1KQzbP_ErWqmWNgKzTyNE7LhnRtstc2D4GJ4FhZuHCZQ"", ""Kế hoạch 2024!g93"")"),1500.0) -> 1500 | Q11: =O11/P11 -> 0
A12: VI | B12: =hyperlink("https://docs.google.com/spreadsheets/d/1NiLWC2P93vOYhLmUW_D3xnNV-9HJraVhA0DrW4_m5jo/edit#gid=0","Trung tâm TMB") -> Trung tâm TMB | C12: 0 | E12: 23.090074 | F12: 22.383743 | G12: 52.119034 | H12: 280.2193 | I12: 40.798678 | J12: 0 | K12: 48.165885 | L12: 174.37022 | M12: 0 | N12: 112.16179 | O12: =sum(C12:N12) -> 753.30872 | P12: =IFERROR(__xludf.DUMMYFUNCTION("IMPORTRANGE(""1KQzbP_ErWqmWNgKzTyNE7LhnRtstc2D4GJ4FhZuHCZQ"", ""Kế hoạch 2024!h93"")"),1000.0) -> 1000 | Q12: =O12/P12 -> 0.75330872
A13: VII | B13: =hyperlink("https://docs.google.com/spreadsheets/d/1qGsXBQA7UK_C9LOomu1EW4PbhsRPWpCf9o9ByaiP77Y/edit#gid=0","Trung tâm BIM") -> Trung tâm BIM | C13: 0 | D13: 2553.284 | E13: 171.875 | F13: 361.63161 | G13: 409.09834 | H13: 0 | I13: 494.06463 | J13: 207.45 | K13: 2785.2658 | L13: 239.78798 | M13: 0 | N13: 0 | O13: =sum(C13:N13) -> 7222.4574 | P13: =IFERROR(__xludf.DUMMYFUNCTION("IMPORTRANGE(""1KQzbP_ErWqmWNgKzTyNE7LhnRtstc2D4GJ4FhZuHCZQ"", ""Kế hoạch 2024!i93"")"),4440.0) -> 4440 | Q13: =O13/P13 -> 1.6266796
A14: VIII | B14: =hyperlink("https://docs.google.com/spreadsheets/d/1TGKe-aBIfi6jlUkNz8gWl8ld-iWWsJOQj3t5hybOWtQ/edit#gid=0","Các lĩnh vực khác") -> Các lĩnh vực khác | C14: 0 | O14: =sum(C14:N14) -> 0 | P14: 0
A15: IX | B15: Tổng chung toàn CT | C15: =SUM(C16:C17) -> 699.52196 | D15: =SUM(D16:D17) -> 3050.9987 | E15: =SUM(E16:E17) -> 3094.3628 | F15: =SUM(F16:F17) -> 1912.4352 | G15: =SUM(G16:G17) -> 3266.1048 | H15: =SUM(H16:H17) -> 2402.5175 | I15: =SUM(I16:I17) -> 2705.1838 | J15: =SUM(J16:J17) -> 1165.5283 | ... N15: =SUM(N16:N17) -> 3005.6189 | O15: =sum(C15:N15) -> 32262.6 | P15: =P17+P16 -> 28140 | Q15: =O15/P15 -> 1.1465032
B16: CIC Hà Nội | C16: =C4+C7+C9+C10+C11+C12+C13+C14 -> 355.34134 | D16: =D4+D7+D9+D10+D11+D12+D13+D14 -> 2874.0617 | E16: =E4+E7+E9+E10+E11+E12+E13+E14 -> 2322.2081 | F16: =F4+F7+F9+F10+F11+F12+F13+F14 -> 1076.3308 | G16: =G4+G7+G9+G10+G11+G12+G13+G14 -> 1810.2587 | H16: =H4+H7+H9+H10+H11+H12+H13+H14 -> 1368.4585 | I16: =I4+I7+I9+I10+I11+I12+I13+I14 -> 2228.4258 | J16: =J4+J7+J9+J10+J11+J12+J13+J14 -> 771.14008 | ... N16: =N4+N7+N9+N10+N11+N12+N13+N14 -> 2391.5698 | O16: =SUM(C16:N16) -> 23384.214 | P16: =P4+P7+P9+P10+P11+P12+P13+P14 -> 20490 | Q16: =O16/P16 -> 1.1412501
B17: CIC Hồ Chí Minh | C17: =C5+C8 -> 344.18061 | D17: =D5+D8 -> 176.93695 | E17: =E5+E8 -> 772.15471 | F17: =F5+F8 -> 836.10442 | G17: =G5+G8 -> 1455.8461 | H17: =H5+H8 -> 1034.059 | I17: =I5+I8 -> 476.75799 | J17: =J5+J8 -> 394.38825 | ... N17: =N5+N8 -> 614.04907 | O17: =SUM(C17:N17) -> 8878.3856 | P17: =P5+P8 -> 7650 | Q17: =O17/P17 -> 1.1605733
B18: Toàn công ty 2023 | C18: =IFERROR(__xludf.DUMMYFUNCTION("IMPORTRANGE(""1mgk5_08R7QPyVWFUtyotwoussHVEv6Lz8ls-NcbSu3U"", ""Lợi nhuận gộp quản trị!C14"")"),2106.1832971498056) -> 2106.1833 | D18: =IFERROR(__xludf.DUMMYFUNCTION("IMPORTRANGE(""1mgk5_08R7QPyVWFUtyotwoussHVEv6Lz8ls-NcbSu3U"", ""Lợi nhuận gộp quản trị!D14"")"),1058.6942950332423) -> 1058.6943 | E18: =IFERROR(__xludf.DUMMYFUNCTION("IMPORTRANGE(""1mgk5_08R7QPyVWFUtyotwoussHVEv6Lz8ls-NcbSu3U"", ""Lợi nhuận gộp quản trị!E14"")"),2834.4682672291483) -> 2834.4683 | F18: =IFERROR(__xludf.DUMMYFUNCTION("IMPORTRANGE(""1mgk5_08R7QPyVWFUtyotwoussHVEv6Lz8ls-NcbSu3U"", ""Lợi nhuận gộp quản trị!F14"")"),1640.263716895778) -> 1640.2637 | G18: =IFERROR(__xludf.DUMMYFUNCTION("IMPORTRANGE(""1mgk5_08R7QPyVWFUtyotwoussHVEv6Lz8ls-NcbSu3U"", ""Lợi nhuận gộp quản trị!G14"")"),1702.9503356165792) -> 1702.9503 | H18: =IFERROR(__xludf.DUMMYFUNCTION("IMPORTRANGE(""1mgk5_08R7QPyVWFUtyotwoussHVEv6Lz8ls-NcbSu3U"", ""Lợi nhuận gộp quản trị!H14"")"),1417.51985533785) -> 1417.5199 | I18: =IFERROR(__xludf.DUMMYFUNCTION("IMPORTRANGE(""1mgk5_08R7QPyVWFUtyotwoussHVEv6Lz8ls-NcbSu3U"", ""Lợi nhuận gộp quản trị!I14"")"),1241.7991817754444) -> 1241.7992 | J18: =IFERROR(__xludf.DUMMYFUNCTION("IMPORTRANGE(""1mgk5_08R7QPyVWFUtyotwoussHVEv6Lz8ls-NcbSu3U"", ""Lợi nhuận gộp quản trị!J14"")"),1975.7471841261404) -> 1975.7472 | K18: =IFERROR(__xludf.DUMMYFUNCTION("IMPORTRANGE(""1mgk5_08R7QPyVWFUtyotwoussHVEv6Lz8ls-NcbSu3U"", ""Lợi nhuận gộp quản trị!K14"")"),2559.4954056203214) -> 2559.4954 | L18: =IFERROR(__xludf.DUMMYFUNCTION("IMPORTRANGE(""1mgk5_08R7QPyVWFUtyotwoussHVEv6Lz8ls-NcbSu3U"", ""Lợi nhuận gộp quản trị!L14"")"),1496.8882693902774) -> 1496.8883 | M18: =IFERROR(__xludf.DUMMYFUNCTION("IMPORTRANGE(""1mgk5_08R7QPyVWFUtyotwoussHVEv6Lz8ls-NcbSu3U"", ""Lợi nhuận gộp quản trị!M14"")"),4630.331321443744) -> 4630.3313 | N18: =IFERROR(__xludf.DUMMYFUNCTION("IMPORTRANGE(""1mgk5_08R7QPyVWFUtyotwoussHVEv6Lz8ls-NcbSu3U"", ""Lợi nhuận gộp quản trị!N14"")"),1193.2422717611112) -> 1193.2423 | O18: =SUM(C18:N18) -> 23857.583
B19: So sánh 2024/2023 | C19: =C15/C18 -> 0.33212777 | D19: =D15/D18 -> 2.8818505 | E19: =E15/E18 -> 1.0916907 | F19: =F15/F18 -> 1.1659315 | G19: =G15/G18 -> 1.9179096 | H19: =H15/H18 -> 1.694874 | I19: =I15/I18 -> 2.178439 | J19: =J15/J18 -> 0.58991775 | ... O19: =O15/O18 -> 1.3522996
B20: SS cùng kỳ năm ngoái | D20: =sum($C15:D15)/sum($C18:D18) -> 1.1850445 | E20: =sum($C15:E15)/sum($C18:E18) -> 1.1409383 | F20: =sum($C15:F15)/sum($C18:F18) -> 1.1463045 | G20: =sum($C15:G15)/sum($C18:G18) -> 1.2869517 | H20: =sum($C15:H15)/sum($C18:H18) -> 1.3406909 | I20: =sum($C15:I15)/sum($C18:I18) -> 1.4273702 | J20: =sum($C15:J15)/sum($C18:J18) -> 1.3089957 | K20: =sum($C15:K15)/sum($C18:K18) -> 1.4869989 | ... N20: =sum($C15:N15)/sum($C18:N18) -> 1.3522996 | O20: Kế hoạch # | P20: 24000 | Q20: =O15/P20 -> 1.344275

Sheet Lợi nhuận gộp theo DT
B1: ='Sản lượng ký kết'!B1 -> 2024 | C1: BẢNG TỔNG HỢP LỢI NHUẬN GỘP THEO DT TỪ 01/01/2024 đến 03/03/2026
A2: STT | B2: Nội dung | C2: Tháng 1 | D2: Tháng 2 | E2: Tháng 3 | F2: Tháng 4 | G2: Tháng 5 | H2: Tháng 6 | I2: Tháng 7 | J2: Tháng 8 | K2: Tháng 9 | L2: Tháng 10 | M2: Tháng 11 | N2: Tháng 12 | O2: Tổng tháng | P2: Kế hoạch năm | Q2: Tỷ lệ % hoàn thành KH
A3: I | B3: Phần mềm xây dựng | C3: =sum(C4:C5) -> 1.925 | D3: =sum(D4:D5) -> 25.35 | E3: =sum(E4:E5) -> 13.775 | F3: =sum(F4:F5) -> 13.5425 | G3: =sum(G4:G5) -> 12.8025 | H3: =sum(H4:H5) -> 17.825 | I3: =sum(I4:I5) -> 26.8 | J3: =sum(J4:J5) -> 14.2675 | ... N3: =sum(N4:N5) -> 963.76333 | O3: =sum(C3:N3) -> 1205.0308 | P3: =SUM(P4:P5) -> 2180 | Q3: =O3/P3 -> 0.55276644
B4: =hyperlink("https://docs.google.com/spreadsheets/d/17IwNqscaZ1nfXkCtx3V_0MEnuLIAYueeNI-uEmyeYNc/edit#gid=0","- Trung tâm PMXD") -> - Trung tâm PMXD | D4: 21.5 | E4: 8 | F4: 4 | G4: 9.2 | H4: 6 | I4: 19.1 | J4: 12.7 | K4: 11.1 | L4: 41.8 | M4: 55.7 | N4: 961.56333 | O4: =sum(C4:N4) -> 1150.6633 | P4: ='Lợi nhuận gộp quản trị'!P4 -> 2000 | Q4: =O4/P4 -> 0.57533167
B5: =hyperlink("https://docs.google.com/spreadsheets/d/1cdAyIuV3KTqwcGe6-vyb1X20cPPkDOOJQy9lqzxxIlg/edit#gid=0","- Chi nhánh") -> - Chi nhánh | C5: 1.925 | D5: 3.85 | E5: 5.775 | F5: 9.5425 | G5: 3.6025 | H5: 11.825 | I5: 7.7 | J5: 1.5675 | K5: 5.28 | L5: 1.1 | N5: 2.2 | O5: =sum(C5:N5) -> 54.3675 | P5: ='Lợi nhuận gộp quản trị'!P5 -> 180 | Q5: =O5/P5 -> 0.30204167
A6: II | B6: Phần mềm XD Nhập khẩu | C6: =SUM(C7:C8) -> 1004.3505 | D6: =SUM(D7:D8) -> 261.60325 | E6: =SUM(E7:E8) -> 975.87637 | F6: =SUM(F7:F8) -> 2931.4318 | G6: =SUM(G7:G8) -> 1508.2827 | H6: =SUM(H7:H8) -> 2810.0994 | I6: =SUM(I7:I8) -> 725.13746 | J6: =SUM(J7:J8) -> 1655.9535 | ... N6: =SUM(N7:N8) -> 1962.408 | O6: =sum(C6:N6) -> 19049.271 | P6: =P8+P7 -> 13670 | Q6: =O6/P6 -> 1.3935092
B7: =hyperlink("https://docs.google.com/spreadsheets/d/1LGiIsREyb4-GdMHXfNtTTkfBPXxtYy4zobyDWot7xQA/edit#gid=0","- Trung tâm DCS") -> - Trung tâm DCS | C7: 657.46984 | D7: 192.97497 | E7: 523.49507 | F7: 2030.7707 | G7: 1031.7667 | H7: 903.79779 | I7: 293.47823 | J7: 756.83088 | K7: 934.44433 | L7: 910.48178 | M7: 350.25069 | N7: 1440.2404 | O7: =sum(C7:N7) -> 10026.001 | P7: ='Lợi nhuận gộp quản trị'!P7 -> 6200 | Q7: =O7/P7 -> 1.617097
B8: =hyperlink("https://docs.google.com/spreadsheets/d/1cdAyIuV3KTqwcGe6-vyb1X20cPPkDOOJQy9lqzxxIlg/edit#gid=0","- Chi nhánh") -> - Chi nhánh | C8: 346.88066 | D8: 68.628278 | E8: 452.3813 | F8: 900.66108 | G8: 476.51603 | H8: 1906.3017 | I8: 431.65922 | J8: 899.12262 | K8: 573.88392 | L8: 2117.5295 | M8: 327.53731 | N8: 522.16767 | O8: =sum(C8:N8) -> 9023.2693 | P8: ='Lợi nhuận gộp quản trị'!P8 -> 7470 | Q8: =O8/P8 -> 1.2079343
A9: III | B9: =hyperlink("https://docs.google.com/spreadsheets/d/17WRbCuo0DVepxTRtwozyxF08Zfve8uQViqsT2QSth8I/edit#gid=0","Trung tâm STC") -> Trung tâm STC | C9: 457.13587 | E9: 247.6328 | F9: 111.44515 | G9: 32.211582 | H9: 558.19908 | I9: 348.77171 | J9: 79.085007 | K9: 594.78522 | L9: 707.0957 | M9: 205.9775 | N9: 482.01053 | O9: =sum(C9:N9) -> 3824.3502 | P9: ='Lợi nhuận gộp quản trị'!P9 -> 4300 | Q9: =O9/P9 -> 0.88938376
A10: VI | B10: =hyperlink("https://docs.google.com/spreadsheets/d/1yTBWEM4qeN7cMsdZosoLoINbcnjIbiM09amCGs1O-XI/edit#gid=0","Trung tâm TVDA") -> Trung tâm TVDA | L10: 6 | M10: 18.452778 | N10: 977.34785 | O10: =sum(C10:N10) -> 1001.8006 | P10: ='Lợi nhuận gộp quản trị'!P10 -> 1050 | Q10: =O10/P10 -> 0.95409583
A11: V | B11: =hyperlink("https://docs.google.com/spreadsheets/d/1RHfET1y4R66vHlp6uC32W0Nz_3ubpd5g4n5dZxWkyaw/edit#gid=0","Trung tâm TVTK") -> Trung tâm TVTK | O11: =sum(C11:N11) -> 0 | P11: ='Lợi nhuận gộp quản trị'!P11 -> 1500 | Q11: =O11/P11 -> 0
A12: VI | B12: =hyperlink("https://docs.google.com/spreadsheets/d/1NiLWC2P93vOYhLmUW_D3xnNV-9HJraVhA0DrW4_m5jo/edit#gid=0","Trung tâm TMB") -> Trung tâm TMB | G12: 22.383743 | H12: 32.829041 | I12: 67.29 | J12: 28.219292 | N12: 27.594495 | O12: =sum(C12:N12) -> 178.31657 | P12: ='Lợi nhuận gộp quản trị'!P12 -> 1000 | Q12: =O12/P12 -> 0.17831657
A13: VII | B13: =hyperlink("https://docs.google.com/spreadsheets/d/1qGsXBQA7UK_C9LOomu1EW4PbhsRPWpCf9o9ByaiP77Y/edit#gid=0","Trung tâm BIM") -> Trung tâm BIM | E13: 1968.7358 | F13: 44.5 | G13: 27.298 | H13: 10.68 | I13: 39.54627 | K13: 2691.865 | N13: 1473.7109 | O13: 2930 | P13: ='Lợi nhuận gộp quản trị'!P13 -> 4440 | Q13: =O13/P13 -> 0.65990991
A14: VIII | B14: =hyperlink("https://docs.google.com/spreadsheets/d/1TGKe-aBIfi6jlUkNz8gWl8ld-iWWsJOQj3t5hybOWtQ/edit#gid=0","Các lĩnh vực khác") -> Các lĩnh vực khác | O14: =sum(C14:N14) -> 0 | P14: ='Lợi nhuận gộp quản trị'!P14 -> 0
A15: IX | B15: Tổng chung toàn CT | C15: =SUM(C16:C17) -> 1463.4114 | D15: =SUM(D16:D17) -> 286.95325 | E15: =SUM(E16:E17) -> 3206.02 | F15: =SUM(F16:F17) -> 3100.9194 | G15: =SUM(G16:G17) -> 1602.9785 | H15: =SUM(H16:H17) -> 3429.6326 | I15: =SUM(I16:I17) -> 1207.5454 | J15: =SUM(J16:J17) -> 1777.5253 | ... N15: =SUM(N16:N17) -> 5886.8351 | O15: =sum(C15:N15) -> 31515.105 | P15: =P17+P16 -> 28140 | Q15: =O15/P15 -> 1.1199398
B16: CIC Hà Nội | C16: =C4+C7+C9+C10+C11+C12+C13+C14 -> 1114.6057 | D16: =D4+D7+D9+D10+D11+D12+D13+D14 -> 214.47497 | E16: =E4+E7+E9+E10+E11+E12+E13+E14 -> 2747.8637 | F16: =F4+F7+F9+F10+F11+F12+F13+F14 -> 2190.7158 | G16: =G4+G7+G9+G10+G11+G12+G13+G14 -> 1122.86 | H16: =H4+H7+H9+H10+H11+H12+H13+H14 -> 1511.5059 | I16: =I4+I7+I9+I10+I11+I12+I13+I14 -> 768.18621 | J16: =J4+J7+J9+J10+J11+J12+J13+J14 -> 876.83518 | ... N16: =N4+N7+N9+N10+N11+N12+N13+N14 -> 5362.4674 | O16: =SUM(C16:N16) -> 22437.468 | P16: =P4+P7+P9+P10+P11+P12+P13+P14 -> 20490 | Q16: =O16/P16 -> 1.0950448
B17: CIC Hồ Chí Minh | C17: =C5+C8 -> 348.80566 | D17: =D5+D8 -> 72.478278 | E17: =E5+E8 -> 458.1563 | F17: =F5+F8 -> 910.20358 | G17: =G5+G8 -> 480.11853 | H17: =H5+H8 -> 1918.1267 | I17: =I5+I8 -> 439.35922 | J17: =J5+J8 -> 900.69012 | ... N17: =N5+N8 -> 524.36767 | O17: =SUM(C17:N17) -> 9077.6368 | P17: =P5+P8 -> 7650 | Q17: =O17/P17 -> 1.1866192
B18: Toàn công ty 2023 | C18: =IFERROR(__xludf.DUMMYFUNCTION("IMPORTRANGE(""1mgk5_08R7QPyVWFUtyotwoussHVEv6Lz8ls-NcbSu3U"", ""Lợi nhuận gộp theo DT!C14"")"),248.9069002964722) -> 248.9069 | D18: =IFERROR(__xludf.DUMMYFUNCTION("IMPORTRANGE(""1mgk5_08R7QPyVWFUtyotwoussHVEv6Lz8ls-NcbSu3U"", ""Lợi nhuận gộp theo DT!D14"")"),2030.9586753716667) -> 2030.9587 | E18: =IFERROR(__xludf.DUMMYFUNCTION("IMPORTRANGE(""1mgk5_08R7QPyVWFUtyotwoussHVEv6Lz8ls-NcbSu3U"", ""Lợi nhuận gộp theo DT!E14"")"),1322.9347849383612) -> 1322.9348 | F18: =IFERROR(__xludf.DUMMYFUNCTION("IMPORTRANGE(""1mgk5_08R7QPyVWFUtyotwoussHVEv6Lz8ls-NcbSu3U"", ""Lợi nhuận gộp theo DT!F14"")"),1031.300649905731) -> 1031.3006 | G18: =IFERROR(__xludf.DUMMYFUNCTION("IMPORTRANGE(""1mgk5_08R7QPyVWFUtyotwoussHVEv6Lz8ls-NcbSu3U"", ""Lợi nhuận gộp theo DT!G14"")"),2589.6352355717663) -> 2589.6352 | H18: =IFERROR(__xludf.DUMMYFUNCTION("IMPORTRANGE(""1mgk5_08R7QPyVWFUtyotwoussHVEv6Lz8ls-NcbSu3U"", ""Lợi nhuận gộp theo DT!H14"")"),1079.7326059316667) -> 1079.7326 | I18: =IFERROR(__xludf.DUMMYFUNCTION("IMPORTRANGE(""1mgk5_08R7QPyVWFUtyotwoussHVEv6Lz8ls-NcbSu3U"", ""Lợi nhuận gộp theo DT!I14"")"),1211.1117261781278) -> 1211.1117 | J18: =IFERROR(__xludf.DUMMYFUNCTION("IMPORTRANGE(""1mgk5_08R7QPyVWFUtyotwoussHVEv6Lz8ls-NcbSu3U"", ""Lợi nhuận gộp theo DT!J14"")"),1387.5140050586667) -> 1387.514 | K18: =IFERROR(__xludf.DUMMYFUNCTION("IMPORTRANGE(""1mgk5_08R7QPyVWFUtyotwoussHVEv6Lz8ls-NcbSu3U"", ""Lợi nhuận gộp theo DT!K14"")"),1608.2833746887952) -> 1608.2834 | L18: =IFERROR(__xludf.DUMMYFUNCTION("IMPORTRANGE(""1mgk5_08R7QPyVWFUtyotwoussHVEv6Lz8ls-NcbSu3U"", ""Lợi nhuận gộp theo DT!L14"")"),2511.610992751389) -> 2511.611 | M18: =IFERROR(__xludf.DUMMYFUNCTION("IMPORTRANGE(""1mgk5_08R7QPyVWFUtyotwoussHVEv6Lz8ls-NcbSu3U"", ""Lợi nhuận gộp theo DT!M14"")"),2668.6460141400657) -> 2668.646 | N18: =IFERROR(__xludf.DUMMYFUNCTION("IMPORTRANGE(""1mgk5_08R7QPyVWFUtyotwoussHVEv6Lz8ls-NcbSu3U"", ""Lợi nhuận gộp theo DT!N14"")"),6264.910587811884) -> 6264.9106 | O18: =SUM(C18:N18) -> 23955.546
B19: So sánh 2024/2023 | C19: =C15/C18 -> 5.8793524 | D19: =D15/D18 -> 0.14128956 | E19: =E15/E18 -> 2.423415 | F19: =F15/F18 -> 3.0068045 | G19: =G15/G18 -> 0.61899781 | H19: =H15/H18 -> 3.1763721 | I19: =I15/I18 -> 0.99705535 | J19: =J15/J18 -> 1.2810864 | ... O19: =O15/O18 -> 1.3155661
B20: SS cùng kỳ năm ngoái | D20: =sum($C15:D15)/sum($C18:D18) -> 0.76774905 | E20: =sum($C15:E15)/sum($C18:E18) -> 1.3757034 | F20: =sum($C15:F15)/sum($C18:F18) -> 1.7386984 | G20: =sum($C15:G15)/sum($C18:G18) -> 1.3372972 | H20: =sum($C15:H15)/sum($C18:H18) -> 1.5764394 | I20: =sum($C15:I15)/sum($C18:I18) -> 1.5026895 | J20: =sum($C15:J15)/sum($C18:J18) -> 1.474486 | K20: =sum($C15:K15)/sum($C18:K18) -> 1.6695214 | ... N20: =sum($C15:N15)/sum($C18:N18) -> 1.3155661 | O20: Kế hoạch # | P20: ='Lợi nhuận gộp quản trị'!P20 -> 24000 | Q20: =O15/P20 -> 1.3131294

Sheet Tổng hợp Tiền về
B1: ='Sản lượng ký kết'!B1 -> 2024 | C1: BẢNG TỔNG HỢP TIỀN VỀ TỪ 01/01/2024 đến 03/03/2026
A2: STT | B2: Nội dung | C2: Tháng 1 | D2: Tháng 2 | E2: Tháng 3 | F2: Tháng 4 | G2: Tháng 5 | H2: Tháng 6 | I2: Tháng 7 | J2: Tháng 8 | K2: Tháng 9 | L2: Tháng 10 | M2: Tháng 11 | N2: Tháng 12 | O2: Tổng tháng
A3: I | B3: Phần mềm xây dựng | C3: =sum(C4:C5) -> 11.5 | D3: =sum(D4:D5) -> 32.2 | E3: =sum(E4:E5) -> 15.8 | F3: =sum(F4:F5) -> 20.85 | G3: =sum(G4:G5) -> 31.15 | H3: =sum(H4:H5) -> 35.8 | I3: =sum(I4:I5) -> 36.3 | J3: =sum(J4:J5) -> 68.0642 | ... N3: =sum(N4:N5) -> 1466.05 | O3: =sum(C3:N3) -> 1837.8142
B4: =hyperlink("https://docs.google.com/spreadsheets/d/17IwNqscaZ1nfXkCtx3V_0MEnuLIAYueeNI-uEmyeYNc/edit#gid=0","- Trung tâm PMXD") -> - Trung tâm PMXD | C4: 8 | D4: 19.5 | E4: 11 | F4: 3.5 | G4: 18.1 | H4: 6.3 | I4: 19.8 | J4: 63.7142 | K4: 9.3 | L4: 46 | M4: 53.2 | N4: 1460.7 | O4: =sum(C4:N4) -> 1719.1142
B5: =hyperlink("https://docs.google.com/spreadsheets/d/1cdAyIuV3KTqwcGe6-vyb1X20cPPkDOOJQy9lqzxxIlg/edit#gid=0","- Chi nhánh") -> - Chi nhánh | C5: 3.5 | D5: 12.7 | E5: 4.8 | F5: 17.35 | G5: 13.05 | H5: 29.5 | I5: 16.5 | J5: 4.35 | K5: 9.6 | L5: 2 | N5: 5.35 | O5: =sum(C5:N5) -> 118.7
A6: II | B6: Phần mềm XD Nhập khẩu | C6: =SUM(C7:C8) -> 6626.126 | D6: =SUM(D7:D8) -> 1951.5052 | E6: =SUM(E7:E8) -> 6596.5554 | F6: =SUM(F7:F8) -> 13930.945 | G6: =SUM(G7:G8) -> 8007.8135 | H6: =SUM(H7:H8) -> 7848.5797 | I6: =SUM(I7:I8) -> 11749.087 | J6: =SUM(J7:J8) -> 6495.1985 | ... N6: =SUM(N7:N8) -> 6330.762 | O6: =sum(C6:N6) -> 93890.25
B7: =hyperlink("https://docs.google.com/spreadsheets/d/1LGiIsREyb4-GdMHXfNtTTkfBPXxtYy4zobyDWot7xQA/edit#gid=0","- Trung tâm DCS") -> - Trung tâm DCS | C7: 2978.91 | D7: 639.23455 | E7: 3979.4473 | F7: 9889.657 | G7: 4257.0423 | H7: 3113.918 | I7: 2588.2916 | J7: 2257.8483 | K7: 944.48415 | L7: 2230.0967 | M7: 5462.6039 | N7: 2621.0201 | O7: =sum(C7:N7) -> 40962.554
B8: =hyperlink("https://docs.google.com/spreadsheets/d/1cdAyIuV3KTqwcGe6-vyb1X20cPPkDOOJQy9lqzxxIlg/edit#gid=0","- Chi nhánh") -> - Chi nhánh | C8: 3647.216 | D8: 1312.2706 | E8: 2617.1081 | F8: 4041.2881 | G8: 3750.7711 | H8: 4734.6617 | I8: 9160.7957 | J8: 4237.3503 | K8: 3755.4392 | L8: 4097.7745 | M8: 7863.2792 | N8: 3709.7419 | O8: =sum(C8:N8) -> 52927.696
A9: III | B9: =hyperlink("https://docs.google.com/spreadsheets/d/17WRbCuo0DVepxTRtwozyxF08Zfve8uQViqsT2QSth8I/edit#gid=0","Trung tâm STC") -> Trung tâm STC | C9: 160.875 | D9: 1245.382 | E9: 1277.2746 | F9: 124.26876 | G9: 1672.977 | H9: 237.495 | I9: 2729.6698 | J9: 1641.0257 | K9: 381.415 | L9: 7261.6012 | M9: 942.4445 | N9: 4359.559 | O9: =sum(C9:N9) -> 22033.988
A10: VI | B10: =hyperlink("https://docs.google.com/spreadsheets/d/1yTBWEM4qeN7cMsdZosoLoINbcnjIbiM09amCGs1O-XI/edit#gid=0","Trung tâm TVDA") -> Trung tâm TVDA | C10: 178.95728 | M10: 28.47 | N10: 64.8 | O10: =sum(C10:N10) -> 272.22728
A11: V | B11: =hyperlink("https://docs.google.com/spreadsheets/d/1RHfET1y4R66vHlp6uC32W0Nz_3ubpd5g4n5dZxWkyaw/edit#gid=0","Trung tâm TVTK") -> Trung tâm TVTK | O11: =sum(C11:N11) -> 0
A12: VI | B12: =hyperlink("https://docs.google.com/spreadsheets/d/1NiLWC2P93vOYhLmUW_D3xnNV-9HJraVhA0DrW4_m5jo/edit#gid=0","Trung tâm TMB") -> Trung tâm TMB | F12: 86.81 | G12: 150.205 | H12: 55.31 | I12: 29.4 | J12: 334.5174 | K12: 89.8 | L12: 28.405 | M12: 252.8007 | N12: 28.5 | O12: =sum(C12:N12) -> 1055.7481
A13: VII | B13: =hyperlink("https://docs.google.com/spreadsheets/d/1qGsXBQA7UK_C9LOomu1EW4PbhsRPWpCf9o9ByaiP77Y/edit#gid=0","Trung tâm BIM") -> Trung tâm BIM | C13: 1231.2 | E13: 562.81697 | F13: 75 | G13: 1439.4 | H13: 1454.0407 | I13: 132.343 | J13: 1727 | K13: 1876.4404 | L13: 136.80816 | M13: 220.01142 | N13: 371.4 | O13: =sum(C13:N13) -> 9226.4606
A14: VIII | B14: =hyperlink("https://docs.google.com/spreadsheets/d/1TGKe-aBIfi6jlUkNz8gWl8ld-iWWsJOQj3t5hybOWtQ/edit#gid=0","Các lĩnh vực khác") -> Các lĩnh vực khác | O14: =sum(C14:N14) -> 0
A15: IX | B15: Tổng chung toàn CT | C15: =SUM(C16:C17) -> 8208.6583 | D15: =SUM(D16:D17) -> 3229.0872 | E15: =SUM(E16:E17) -> 8452.447 | F15: =SUM(F16:F17) -> 14237.874 | G15: =SUM(G16:G17) -> 11301.546 | H15: =SUM(H16:H17) -> 9631.2253 | I15: =SUM(I16:I17) -> 14676.8 | J15: =SUM(J16:J17) -> 10265.806 | ... N15: =SUM(N16:N17) -> 12621.071 | O15: =sum(C15:N15) -> 128316.49
B16: CIC Hà Nội | C16: =C4+C7+C9+C10+C11+C12+C13+C14 -> 4557.9423 | D16: =D4+D7+D9+D10+D11+D12+D13+D14 -> 1904.1165 | E16: =E4+E7+E9+E10+E11+E12+E13+E14 -> 5830.5389 | F16: =F4+F7+F9+F10+F11+F12+F13+F14 -> 10179.236 | G16: =G4+G7+G9+G10+G11+G12+G13+G14 -> 7537.7244 | H16: =H4+H7+H9+H10+H11+H12+H13+H14 -> 4867.0637 | I16: =I4+I7+I9+I10+I11+I12+I13+I14 -> 5499.5044 | J16: =J4+J7+J9+J10+J11+J12+J13+J14 -> 6024.1055 | ... N16: =N4+N7+N9+N10+N11+N12+N13+N14 -> 8905.9791 | O16: =sum(C16:N16) -> 75270.092
B17: CIC Hồ Chí Minh | C17: =C5+C8 -> 3650.716 | D17: =D5+D8 -> 1324.9706 | E17: =E5+E8 -> 2621.9081 | F17: =F5+F8 -> 4058.6381 | G17: =G5+G8 -> 3763.8211 | H17: =H5+H8 -> 4764.1617 | I17: =I5+I8 -> 9177.2957 | J17: =J5+J8 -> 4241.7003 | ... N17: =N5+N8 -> 3715.0919 | O17: =sum(C17:N17) -> 53046.396

Sheet Thống kê danh sách các hợp đồng
A1: Số hợp đồng | B1: Nội dung hợp đồng | C1: Khách hàng | D1: Ngày ký | E1: Ngày ghi DT | F1: Ký kết | G1: Doanh thu | H1: Lợi nhuận gộp | I1: Tiền về | J1: Tỷ suất LN/DT
F2: =sum(F4:F831)/2 -> 167480579215 | G2: =sum(G4:G831)/2 -> 125181878542 | H2: =sum(H4:H831)/2 -> 32034269461 | I2: =sum(I4:I831)/2 -> 114629262515
F3: =F2/1000000/'Sản lượng ký kết'!P20 -> 1.8608953 | G3: =G2/1000000/'Tổng hợp Doanh thu'!P20 -> 1.5647735 | H3: =H2/1000000/'Lợi nhuận gộp quản trị'!P20 -> 1.3347612
A4: Trung tâm Phần mềm Xây dựng | F4: =sum(F5:F66) -> 3800714000 | G4: =sum(G5:G66) -> 2071324075 | H4: =sum(H5:H66) -> 1558070741 | I4: =sum(I5:I66) -> 2082714200
A5: VV01 | B5: KIW | C5: Công ty Cổ phần xây dựng Đức Anh | F5: 8000000 | I5: 8000000 | J5: =H5/G5 -> #DIV/0!
A6: vv02/2024 | B6: Escon 15 | C6: Công Ty TNHH Phát Triển Xây Dựng Hoàng Thắng | F6: 300000 | J6: =H6/G6 -> #DIV/0!
A7: vv03/2024 | B7: RDW | C7: Công ty TNHH tư vấn thiết kế xây dựng Ngân Phát – Gia Lai | E7: 45323.625 | F7: 10000000 | G7: 10000000 | H7: 10000000 | I7: 18000000 | J7: =H7/G7 -> 1
A8: vv03/2024 | B8: MBW | C8: Công ty TNHH tư vấn thiết kế xây dựng Ngân Phát – Gia Lai | E8: 45323.625 | F8: 8000000 | G8: 8000000 | H8: 8000000 | J8: =H8/G8 -> 1
A9: vv54/2023 | B9: SUMAC | C9: Trần Tuyến | E9: 45342.625 | F9: 2000000 | G9: 2000000 | H9: 2000000 | I9: 2000000 | J9: =H9/G9 -> 1
A10: vv55/2024 | B10: Escon 15 | C10: Nguyễn Danh Kiên | E10: 45351.625 | F10: 1500000 | G10: 1500000 | H10: 1500000 | I10: 1500000 | J10: =H10/G10 -> 1
A11: vv04/2024 | B11: Escon 15 | C11: Công ty Cổ phần Thương Mại và Xây dựng nhà ở Đô Thị Lào Cai | E11: 45363.583 | F11: 4000000 | G11: 4000000 | H11: 4000000 | I11: 4000000 | J11: =H11/G11 -> 1
A12: vv05 | B12: Stcad | C12: Vi Hồng Mạnh | E12: 45511.583 | F12: 1500000 | G12: 1500000 | H12: 1500000 | I12: 1500000 | J12: =H12/G12 -> 1
A13: VV06 | B13: SUMAC | C13: Anh Viễn | E13: 45511.583 | F13: 1500000 | G13: 1500000 | H13: 1500000 | I13: 1500000 | J13: =H13/G13 -> 1
A14: VV07 | B14: Escon 15 | C14: Công ty TNHH MTV An thuận Phát | E14: 45376.583 | F14: 4000000 | G14: 4000000 | H14: 4000000 | I14: 4000000 | J14: =H14/G14 -> 1
A15: vv08/2024 | B15: SUMAC | C15: CÔNG TY CP ĐẦU TƯ XD VÀ TM TRIVICO HÀ NỘI | E15: 45511.583 | F15: 1500000 | G15: 1500000 | H15: 1500000 | I15: 1500000 | J15: =H15/G15 -> 1
A16: vv09/2024 | B16: Escon 15 | C16: cty tnhh An hội Kon Tum | E16: 45511.583 | F16: 1000000 | G16: 1000000 | H16: 1000000 | I16: 1000000 | J16: =H16/G16 -> 1
A17: vv10/2024 | B17: Escon 15 | C17: Trần Thị Kim Thanh | E17: 45511.583 | F17: 1000000 | G17: 1000000 | H17: 1000000 | I17: 1000000 | J17: =H17/G17 -> 1
A18: VV11 | B18: Escon 15 | C18: Chi nhánh phát điện dầu khí - tập đoàn dầu khí Việt Nam | E18: 45404.583 | F18: 4000000 | G18: 4000000 | H18: 4000000 | I18: 4000000 | J18: =H18/G18 -> 1
A19: vv12/2024 | B19: SUMAC | C19: CÔNG TY TNHH TAISEI ROTEC VIỆT NAM | E19: 45419.583 | F19: 2500000 | G19: 2500000 | H19: 2000000 | I19: 2500000 | J19: =H19/G19 -> 0.8
A20: vv13/2024 | B20: Escon 15 | C20: Nguyễn Thị Hoa | E20: 45511.583 | F20: 3600000 | G20: 3600000 | H20: 3600000 | I20: 3600000 | J20: =H20/G20 -> 1
... A30: HĐ01/SXDNB-CIC | B30: Lập đơn giá | C30: Tư vấn lập Chỉ số giá xây dựng, Đơn giá nhân công xây dựng, Bảng giá ca máy và thiết bị trên địa bàn tỉnh Ninh Bình năm 2024 | E30: 45652.625 | F30: 475000000 | G30: 439814815 | H30: 2.6388889e+08 | I30: 475000000 | J30: =H30/G30 -> 0.6
A31: VV23 | C31: Trung tâm giám định CLXD tỉnh lào cai | E31: 45511.583 | F31: 300000 | G31: 300000 | H31: 300000 | I31: 300000 | J31: =H31/G31 -> 1
A32: HĐ02/SXDTN-CIC | B32: Lập đơn giá | C32: Tính toán công bố Chỉ số giá xây dựng tỉnh Thái Nguyên năm 2024 | E32: 45651.625 | F32: 201000000 | G32: 186111111 | H32: 37222222 | I32: 201000000 | J32: =H32/G32 -> 0.2
A33: HĐ03/SXDBK-CIC | B33: Lập đơn giá | C33: Xác định chỉ số giá xây dựng năm 2024 trên địa bàn tỉnh Bắc Kạn | E33: 45656.625 | F33: 204714000 | G33: 189550000 | H33: 113730000 | I33: 61414200 | J33: =H33/G33 -> 0.6
A34: vv24 | B34: SUMAC | C34: CÔNG TY TNHH ĐẦU TƯ XÂY DỰNG MEC VIỆT NAM | E34: 45524.583 | F34: 2000000 | G34: 2000000 | H34: 2000000 | I34: 2000000 | J34: =H34/G34 -> 1
A35: vv25/2024 | B35: KIW | C35: Công Ty Cổ Phần Công Nghiệp XD 204 | E35: 45565.583 | F35: 300000 | G35: 300000 | H35: 300000 | I35: 300000 | J35: =H35/G35 -> 1
A36: HĐ04/SXDTN-CIC | B36: Lập đơn giá | C36: Xây dựng bộ đơn giá Dịch vụ công ích đô thị trên địa bàn tỉnh Thái Nguyên | E36: 45646.625 | F36: 288000000 | G36: 266666667 | H36: 53333333 | I36: 288000000 | J36: =H36/G36 -> 0.2
A37: HĐ05/SXDNB-CIC_MCUS | B37: Lập đơn giá | C37: Lập Bộ đơn giá nhà cửa, vật kiến trúc trên địa bàn tỉnh Ninh Bình | E37: 45652.625 | F37: 452000000 | G37: 334814815 | H37: 2.0088889e+08 | I37: 361600000 | J37: =H37/G37 -> 0.6
A38: HĐ06/SXDSL-CIC | B38: Lập đơn giá | C38: Lập đơn giá nhân công xây dựng; đơn giá ca máy, thiết bị thi công xây dựng và đơn giá xây dựng công trình trên địa bàn tỉnh Sơn La | F38: 1500000000 | H38: 4.0740741e+08 | J38: =H38/G38 -> #DIV/0!
A39: vv26 | B39: Escon 15 | C39: Trung tâm giám định CLXD tỉnh lào cai | E39: 45565.583 | F39: 300000 | G39: 300000 | H39: 300000 | I39: 300000 | J39: =H39/G39 -> 1
A40: vv27 | B40: Escon 15 | C40: Đỗ Quang Khanh | E40: 45565.583 | F40: 1500000 | G40: 1500000 | H40: 1500000 | I40: 1500000 | J40: =H40/G40 -> 1
A41: vv28 | B41: Escon 15 | C41: Trung tâm dịch vụ khu kinh tế Lào Cai | E41: 45561.583 | F41: 1500000 | G41: 1500000 | H41: 1500000 | I41: 1500000 | J41: =H41/G41 -> 1
A42: vv29/2024 | B42: Escon 15 | C42: Chi Nhánh Công Ty Cp Cấp Nước Tỉnh Lào Cai Huyện Bát Xát | E42: 45562.583 | F42: 1500000 | G42: 1500000 | H42: 1500000 | I42: 1500000 | J42: =H42/G42 -> 1
A43: HD07/PMXD2024 | B43: Escon 15 | C43: Công Ty Cổ Phần Cấp Nước Tỉnh Lào Cai | E43: 45566.583 | F43: 16000000 | G43: 16000000 | H43: 14400000 | I43: 16000000 | J43: =H43/G43 -> 0.9
A44: vv30/2024 | B44: SUMAC | C44: Công ty cổ phần tư vấn đầu tư xây dựng công trình công nghiệp và đô thị | E44: 45565.583 | F44: 6000000 | G44: 6000000 | H44: 6000000 | I44: 6000000 | J44: =H44/G44 -> 1
A45: vv31/2024 | B45: Vinasas | C45: Công ty CP tư vấn đầu tư xây dựng công trình công nghiệp và đô thị | E45: 45574.583 | F45: 10000000 | G45: 10000000 | H45: 10000000 | I45: 10000000 | J45: =H45/G45 -> 1
A46: vv32/2024 (HD08) | B46: Escon 15 | C46: Công ty cổ phần đầu tư và xây dựng Mộc Châu | E46: 45580.583 | F46: 3000000 | G46: 3000000 | H46: 3000000 | I46: 3000000 | J46: =H46/G46 -> 1
A47: VV33/2024 | B47: Escon 15 | C47: Công ty cổ phần tư vấn đầu tư Á Châu | E47: 45586.583 | F47: 7200000 | G47: 7200000 | H47: 7200000 | I47: 7200000 | J47: =H47/G47 -> 1
A48: vv34/2024 | B48: Escon 15 | C48: Công ty TNHH An đạt thịnh | E48: 45588.583 | F48: 8000000 | G48: 8000000 | H48: 7200000 | I48: 8000000 | J48: =H48/G48 -> 0.9
A49: vv35 | B49: Escon 15 | C49: Trung tâm giám định CLXD tỉnh lào cai | E49: 45653.625 | F49: 300000 | G49: 300000 | H49: 300000 | I49: 300000 | J49: =H49/G49 -> 1
...
